package thaumcraft.common.world.objects;
import java.util.Random;
import net.minecraft.block.Block;
import net.minecraft.init.Blocks;
import net.minecraft.tileentity.TileEntityChest;
import net.minecraft.tileentity.TileEntityMobSpawner;
import net.minecraft.util.ResourceLocation;
import net.minecraft.util.math.BlockPos;
import net.minecraft.world.World;
import net.minecraft.world.gen.feature.WorldGenerator;
import net.minecraft.world.storage.loot.LootTableList;
import thaumcraft.api.blocks.BlocksTC;


public class WorldGenMound extends WorldGenerator
{
    protected Block[] GetValidSpawnBlocks() {
        return new Block[] { Blocks.STONE, Blocks.GRASS, Blocks.DIRT };
    }
    
    public boolean LocationIsValidSpawn(World world, BlockPos pos) {
        int distanceToAir;
        for (distanceToAir = 0; !world.isAirBlock(pos.up(distanceToAir)) && distanceToAir < 3; ++distanceToAir) {}
        if (distanceToAir > 2) {
            return false;
        }
        BlockPos pos2 = pos.up(distanceToAir - 1);
        Block blockID = world.getBlockState(pos2).getBlock();
        Block blockIDBelow = world.getBlockState(pos2.down()).getBlock();
        for (Block x : GetValidSpawnBlocks()) {
            if (!world.isAirBlock(pos2.up())) {
                return false;
            }
            if (blockID == x) {
                return true;
            }
            if ((blockID == Blocks.SNOW_LAYER || blockID == Blocks.TALLGRASS) && blockIDBelow == x) {
                return true;
            }
        }
        return false;
    }
    
    public boolean generate(World world, Random rand, BlockPos pos) {
        int i = pos.getX();
        int j = pos.getY();
        int k = pos.getZ();
        if (!LocationIsValidSpawn(world, new BlockPos(i + 9, j + 9, k + 9)) || !LocationIsValidSpawn(world, new BlockPos(i, j + 9, k)) || !LocationIsValidSpawn(world, new BlockPos(i + 18, j + 9, k)) || !LocationIsValidSpawn(world, new BlockPos(i + 18, j + 9, k + 18)) || !LocationIsValidSpawn(world, new BlockPos(i, j + 9, k + 18))) {
            return false;
        }
        world.setBlockState(new BlockPos(i + 0, j + 8, k + 4), Blocks.DIRT.getDefaultState());
        world.setBlockState(new BlockPos(i + 0, j + 8, k + 5), Blocks.DIRT.getDefaultState());
        world.setBlockState(new BlockPos(i + 0, j + 8, k + 6), Blocks.DIRT.getDefaultState());
        world.setBlockState(new BlockPos(i + 0, j + 8, k + 7), Blocks.DIRT.getDefaultState());
        world.setBlockState(new BlockPos(i + 0, j + 8, k + 8), Blocks.COBBLESTONE.getDefaultState());
        world.setBlockState(new BlockPos(i + 0, j + 8, k + 9), Blocks.COBBLESTONE.getDefaultState());
        world.setBlockState(new BlockPos(i + 0, j + 8, k + 10), Blocks.COBBLESTONE.getDefaultState());
        world.setBlockState(new BlockPos(i + 0, j + 8, k + 11), Blocks.DIRT.getDefaultState());
        world.setBlockState(new BlockPos(i + 0, j + 8, k + 12), Blocks.DIRT.getDefaultState());
        world.setBlockState(new BlockPos(i + 0, j + 8, k + 13), Blocks.DIRT.getDefaultState());
        world.setBlockState(new BlockPos(i + 0, j + 8, k + 14), Blocks.DIRT.getDefaultState());
        world.setBlockState(new BlockPos(i + 0, j + 9, k + 4), Blocks.GRASS.getDefaultState());
        world.setBlockState(new BlockPos(i + 0, j + 9, k + 5), Blocks.GRASS.getDefaultState());
        world.setBlockState(new BlockPos(i + 0, j + 9, k + 6), Blocks.GRASS.getDefaultState());
        world.setBlockState(new BlockPos(i + 0, j + 9, k + 7), Blocks.GRASS.getDefaultState());
        world.setBlockState(new BlockPos(i + 0, j + 9, k + 8), Blocks.STONE_STAIRS.getStateFromMeta(0));
        world.setBlockState(new BlockPos(i + 0, j + 9, k + 9), Blocks.AIR.getDefaultState());
        world.setBlockState(new BlockPos(i + 0, j + 9, k + 10), Blocks.STONE_STAIRS.getStateFromMeta(0));
        world.setBlockState(new BlockPos(i + 0, j + 9, k + 11), Blocks.GRASS.getDefaultState());
        world.setBlockState(new BlockPos(i + 0, j + 9, k + 12), Blocks.GRASS.getDefaultState());
        world.setBlockState(new BlockPos(i + 0, j + 9, k + 13), Blocks.GRASS.getDefaultState());
        world.setBlockState(new BlockPos(i + 0, j + 9, k + 14), Blocks.GRASS.getDefaultState());
        world.setBlockState(new BlockPos(i + 0, j + 10, k + 8), Blocks.AIR.getDefaultState());
        world.setBlockState(new BlockPos(i + 0, j + 10, k + 9), Blocks.AIR.getDefaultState());
        world.setBlockState(new BlockPos(i + 0, j + 10, k + 10), Blocks.AIR.getDefaultState());
        world.setBlockState(new BlockPos(i + 1, j + 8, k + 3), Blocks.DIRT.getDefaultState());
        world.setBlockState(new BlockPos(i + 1, j + 8, k + 4), Blocks.DIRT.getDefaultState());
        world.setBlockState(new BlockPos(i + 1, j + 8, k + 5), Blocks.DIRT.getDefaultState());
        world.setBlockState(new BlockPos(i + 1, j + 8, k + 6), Blocks.DIRT.getDefaultState());
        world.setBlockState(new BlockPos(i + 1, j + 8, k + 7), Blocks.DIRT.getDefaultState());
        world.setBlockState(new BlockPos(i + 1, j + 8, k + 8), Blocks.COBBLESTONE.getDefaultState());
        world.setBlockState(new BlockPos(i + 1, j + 8, k + 9), Blocks.COBBLESTONE.getDefaultState());
        world.setBlockState(new BlockPos(i + 1, j + 8, k + 10), Blocks.COBBLESTONE.getDefaultState());
        world.setBlockState(new BlockPos(i + 1, j + 8, k + 11), Blocks.DIRT.getDefaultState());
        world.setBlockState(new BlockPos(i + 1, j + 8, k + 12), Blocks.DIRT.getDefaultState());
        world.setBlockState(new BlockPos(i + 1, j + 8, k + 13), Blocks.DIRT.getDefaultState());
        world.setBlockState(new BlockPos(i + 1, j + 8, k + 14), Blocks.DIRT.getDefaultState());
        world.setBlockState(new BlockPos(i + 1, j + 8, k + 15), Blocks.DIRT.getDefaultState());
        world.setBlockState(new BlockPos(i + 1, j + 9, k + 3), Blocks.GRASS.getDefaultState());
        world.setBlockState(new BlockPos(i + 1, j + 9, k + 4), Blocks.DIRT.getDefaultState());
        world.setBlockState(new BlockPos(i + 1, j + 9, k + 5), Blocks.DIRT.getDefaultState());
        world.setBlockState(new BlockPos(i + 1, j + 9, k + 6), Blocks.DIRT.getDefaultState());
        world.setBlockState(new BlockPos(i + 1, j + 9, k + 7), Blocks.DIRT.getDefaultState());
        world.setBlockState(new BlockPos(i + 1, j + 9, k + 8), Blocks.COBBLESTONE.getDefaultState());
        world.setBlockState(new BlockPos(i + 1, j + 9, k + 9), Blocks.AIR.getDefaultState());
        world.setBlockState(new BlockPos(i + 1, j + 9, k + 10), Blocks.COBBLESTONE.getDefaultState());
        world.setBlockState(new BlockPos(i + 1, j + 9, k + 11), Blocks.DIRT.getDefaultState());
        world.setBlockState(new BlockPos(i + 1, j + 9, k + 12), Blocks.DIRT.getDefaultState());
        world.setBlockState(new BlockPos(i + 1, j + 9, k + 13), Blocks.DIRT.getDefaultState());
        world.setBlockState(new BlockPos(i + 1, j + 9, k + 14), Blocks.DIRT.getDefaultState());
        world.setBlockState(new BlockPos(i + 1, j + 9, k + 15), Blocks.GRASS.getDefaultState());
        world.setBlockState(new BlockPos(i + 1, j + 10, k + 4), Blocks.GRASS.getDefaultState());
        world.setBlockState(new BlockPos(i + 1, j + 10, k + 5), Blocks.GRASS.getDefaultState());
        world.setBlockState(new BlockPos(i + 1, j + 10, k + 6), Blocks.DIRT.getDefaultState());
        world.setBlockState(new BlockPos(i + 1, j + 10, k + 7), Blocks.DIRT.getDefaultState());
        world.setBlockState(new BlockPos(i + 1, j + 10, k + 8), Blocks.STONE_STAIRS.getStateFromMeta(0));
        world.setBlockState(new BlockPos(i + 1, j + 10, k + 9), Blocks.AIR.getDefaultState());
        world.setBlockState(new BlockPos(i + 1, j + 10, k + 10), Blocks.STONE_STAIRS.getStateFromMeta(0));
        world.setBlockState(new BlockPos(i + 1, j + 10, k + 11), Blocks.GRASS.getDefaultState());
        world.setBlockState(new BlockPos(i + 1, j + 10, k + 12), Blocks.GRASS.getDefaultState());
        world.setBlockState(new BlockPos(i + 1, j + 10, k + 13), Blocks.GRASS.getDefaultState());
        world.setBlockState(new BlockPos(i + 1, j + 10, k + 14), Blocks.GRASS.getDefaultState());
        world.setBlockState(new BlockPos(i + 1, j + 11, k + 6), Blocks.GRASS.getDefaultState());
        world.setBlockState(new BlockPos(i + 1, j + 11, k + 7), Blocks.GRASS.getDefaultState());
        world.setBlockState(new BlockPos(i + 1, j + 11, k + 8), Blocks.AIR.getDefaultState());
        world.setBlockState(new BlockPos(i + 1, j + 11, k + 9), Blocks.AIR.getDefaultState());
        world.setBlockState(new BlockPos(i + 1, j + 11, k + 10), Blocks.AIR.getDefaultState());
        world.setBlockState(new BlockPos(i + 2, j + 8, k + 2), Blocks.DIRT.getDefaultState());
        world.setBlockState(new BlockPos(i + 2, j + 8, k + 3), Blocks.DIRT.getDefaultState());
        world.setBlockState(new BlockPos(i + 2, j + 8, k + 4), Blocks.DIRT.getDefaultState());
        world.setBlockState(new BlockPos(i + 2, j + 8, k + 5), Blocks.DIRT.getDefaultState());
        world.setBlockState(new BlockPos(i + 2, j + 8, k + 6), Blocks.DIRT.getDefaultState());
        world.setBlockState(new BlockPos(i + 2, j + 8, k + 7), Blocks.COBBLESTONE.getDefaultState());
        world.setBlockState(new BlockPos(i + 2, j + 8, k + 8), Blocks.COBBLESTONE.getDefaultState());
        world.setBlockState(new BlockPos(i + 2, j + 8, k + 9), Blocks.MOSSY_COBBLESTONE.getDefaultState());
        world.setBlockState(new BlockPos(i + 2, j + 8, k + 10), Blocks.COBBLESTONE.getDefaultState());
        world.setBlockState(new BlockPos(i + 2, j + 8, k + 11), Blocks.COBBLESTONE.getDefaultState());
        world.setBlockState(new BlockPos(i + 2, j + 8, k + 12), Blocks.DIRT.getDefaultState());
        world.setBlockState(new BlockPos(i + 2, j + 8, k + 13), Blocks.DIRT.getDefaultState());
        world.setBlockState(new BlockPos(i + 2, j + 8, k + 14), Blocks.DIRT.getDefaultState());
        world.setBlockState(new BlockPos(i + 2, j + 8, k + 15), Blocks.DIRT.getDefaultState());
        world.setBlockState(new BlockPos(i + 2, j + 8, k + 16), Blocks.DIRT.getDefaultState());
        world.setBlockState(new BlockPos(i + 2, j + 9, k + 2), Blocks.GRASS.getDefaultState());
        world.setBlockState(new BlockPos(i + 2, j + 9, k + 3), Blocks.DIRT.getDefaultState());
        world.setBlockState(new BlockPos(i + 2, j + 9, k + 4), Blocks.DIRT.getDefaultState());
        world.setBlockState(new BlockPos(i + 2, j + 9, k + 5), Blocks.DIRT.getDefaultState());
        world.setBlockState(new BlockPos(i + 2, j + 9, k + 6), Blocks.DIRT.getDefaultState());
        world.setBlockState(new BlockPos(i + 2, j + 9, k + 7), Blocks.DIRT.getDefaultState());
        world.setBlockState(new BlockPos(i + 2, j + 9, k + 8), Blocks.COBBLESTONE.getDefaultState());
        world.setBlockState(new BlockPos(i + 2, j + 9, k + 9), Blocks.AIR.getDefaultState());
        world.setBlockState(new BlockPos(i + 2, j + 9, k + 10), Blocks.COBBLESTONE.getDefaultState());
        world.setBlockState(new BlockPos(i + 2, j + 9, k + 11), Blocks.DIRT.getDefaultState());
        world.setBlockState(new BlockPos(i + 2, j + 9, k + 12), Blocks.DIRT.getDefaultState());
        world.setBlockState(new BlockPos(i + 2, j + 9, k + 13), Blocks.DIRT.getDefaultState());
        world.setBlockState(new BlockPos(i + 2, j + 9, k + 14), Blocks.DIRT.getDefaultState());
        world.setBlockState(new BlockPos(i + 2, j + 9, k + 15), Blocks.DIRT.getDefaultState());
        world.setBlockState(new BlockPos(i + 2, j + 9, k + 16), Blocks.GRASS.getDefaultState());
        world.setBlockState(new BlockPos(i + 2, j + 10, k + 3), Blocks.GRASS.getDefaultState());
        world.setBlockState(new BlockPos(i + 2, j + 10, k + 4), Blocks.DIRT.getDefaultState());
        world.setBlockState(new BlockPos(i + 2, j + 10, k + 5), Blocks.DIRT.getDefaultState());
        world.setBlockState(new BlockPos(i + 2, j + 10, k + 6), Blocks.DIRT.getDefaultState());
        world.setBlockState(new BlockPos(i + 2, j + 10, k + 7), Blocks.DIRT.getDefaultState());
        world.setBlockState(new BlockPos(i + 2, j + 10, k + 8), Blocks.COBBLESTONE.getDefaultState());
        world.setBlockState(new BlockPos(i + 2, j + 10, k + 9), Blocks.AIR.getDefaultState());
        world.setBlockState(new BlockPos(i + 2, j + 10, k + 10), Blocks.MOSSY_COBBLESTONE.getDefaultState());
        world.setBlockState(new BlockPos(i + 2, j + 10, k + 11), Blocks.DIRT.getDefaultState());
        world.setBlockState(new BlockPos(i + 2, j + 10, k + 12), Blocks.DIRT.getDefaultState());
        world.setBlockState(new BlockPos(i + 2, j + 10, k + 13), Blocks.DIRT.getDefaultState());
        world.setBlockState(new BlockPos(i + 2, j + 10, k + 14), Blocks.DIRT.getDefaultState());
        world.setBlockState(new BlockPos(i + 2, j + 10, k + 15), Blocks.GRASS.getDefaultState());
        world.setBlockState(new BlockPos(i + 2, j + 11, k + 4), Blocks.GRASS.getDefaultState());
        world.setBlockState(new BlockPos(i + 2, j + 11, k + 5), Blocks.GRASS.getDefaultState());
        world.setBlockState(new BlockPos(i + 2, j + 11, k + 6), Blocks.DIRT.getDefaultState());
        world.setBlockState(new BlockPos(i + 2, j + 11, k + 7), Blocks.DIRT.getDefaultState());
        world.setBlockState(new BlockPos(i + 2, j + 11, k + 8), Blocks.COBBLESTONE.getDefaultState());
        world.setBlockState(new BlockPos(i + 2, j + 11, k + 9), Blocks.STONEBRICK.getStateFromMeta(3));
        world.setBlockState(new BlockPos(i + 2, j + 11, k + 10), Blocks.MOSSY_COBBLESTONE.getDefaultState());
        world.setBlockState(new BlockPos(i + 2, j + 11, k + 11), Blocks.DIRT.getDefaultState());
        world.setBlockState(new BlockPos(i + 2, j + 11, k + 12), Blocks.GRASS.getDefaultState());
        world.setBlockState(new BlockPos(i + 2, j + 11, k + 13), Blocks.GRASS.getDefaultState());
        world.setBlockState(new BlockPos(i + 2, j + 11, k + 14), Blocks.GRASS.getDefaultState());
        world.setBlockState(new BlockPos(i + 2, j + 12, k + 6), Blocks.GRASS.getDefaultState());
        world.setBlockState(new BlockPos(i + 2, j + 12, k + 7), Blocks.GRASS.getDefaultState());
        world.setBlockState(new BlockPos(i + 2, j + 12, k + 8), Blocks.GRASS.getDefaultState());
        world.setBlockState(new BlockPos(i + 2, j + 12, k + 9), Blocks.GRASS.getDefaultState());
        world.setBlockState(new BlockPos(i + 2, j + 12, k + 10), Blocks.GRASS.getDefaultState());
        world.setBlockState(new BlockPos(i + 2, j + 12, k + 11), Blocks.GRASS.getDefaultState());
        world.setBlockState(new BlockPos(i + 3, j + 4, k + 3), Blocks.COBBLESTONE.getDefaultState());
        world.setBlockState(new BlockPos(i + 3, j + 4, k + 4), Blocks.COBBLESTONE.getDefaultState());
        world.setBlockState(new BlockPos(i + 3, j + 4, k + 5), Blocks.COBBLESTONE.getDefaultState());
        world.setBlockState(new BlockPos(i + 3, j + 4, k + 6), Blocks.COBBLESTONE.getDefaultState());
        world.setBlockState(new BlockPos(i + 3, j + 4, k + 7), Blocks.COBBLESTONE.getDefaultState());
        world.setBlockState(new BlockPos(i + 3, j + 4, k + 8), Blocks.COBBLESTONE.getDefaultState());
        world.setBlockState(new BlockPos(i + 3, j + 4, k + 9), Blocks.COBBLESTONE.getDefaultState());
        world.setBlockState(new BlockPos(i + 3, j + 4, k + 10), Blocks.COBBLESTONE.getDefaultState());
        world.setBlockState(new BlockPos(i + 3, j + 4, k + 11), Blocks.COBBLESTONE.getDefaultState());
        world.setBlockState(new BlockPos(i + 3, j + 4, k + 12), Blocks.COBBLESTONE.getDefaultState());
        world.setBlockState(new BlockPos(i + 3, j + 4, k + 13), Blocks.COBBLESTONE.getDefaultState());
        world.setBlockState(new BlockPos(i + 3, j + 4, k + 14), Blocks.COBBLESTONE.getDefaultState());
        world.setBlockState(new BlockPos(i + 3, j + 4, k + 15), Blocks.COBBLESTONE.getDefaultState());
        world.setBlockState(new BlockPos(i + 3, j + 5, k + 3), Blocks.COBBLESTONE.getDefaultState());
        world.setBlockState(new BlockPos(i + 3, j + 5, k + 4), Blocks.COBBLESTONE.getDefaultState());
        world.setBlockState(new BlockPos(i + 3, j + 5, k + 5), Blocks.COBBLESTONE.getDefaultState());
        world.setBlockState(new BlockPos(i + 3, j + 5, k + 6), Blocks.COBBLESTONE.getDefaultState());
        world.setBlockState(new BlockPos(i + 3, j + 5, k + 7), Blocks.MOSSY_COBBLESTONE.getDefaultState());
        world.setBlockState(new BlockPos(i + 3, j + 5, k + 8), Blocks.MOSSY_COBBLESTONE.getDefaultState());
        world.setBlockState(new BlockPos(i + 3, j + 5, k + 9), Blocks.COBBLESTONE.getDefaultState());
        world.setBlockState(new BlockPos(i + 3, j + 5, k + 10), Blocks.COBBLESTONE.getDefaultState());
        world.setBlockState(new BlockPos(i + 3, j + 5, k + 11), Blocks.COBBLESTONE.getDefaultState());
        world.setBlockState(new BlockPos(i + 3, j + 5, k + 12), Blocks.COBBLESTONE.getDefaultState());
        world.setBlockState(new BlockPos(i + 3, j + 5, k + 13), Blocks.COBBLESTONE.getDefaultState());
        world.setBlockState(new BlockPos(i + 3, j + 5, k + 14), Blocks.COBBLESTONE.getDefaultState());
        world.setBlockState(new BlockPos(i + 3, j + 5, k + 15), Blocks.COBBLESTONE.getDefaultState());
        world.setBlockState(new BlockPos(i + 3, j + 6, k + 3), Blocks.COBBLESTONE.getDefaultState());
        world.setBlockState(new BlockPos(i + 3, j + 6, k + 4), Blocks.COBBLESTONE.getDefaultState());
        world.setBlockState(new BlockPos(i + 3, j + 6, k + 5), Blocks.COBBLESTONE.getDefaultState());
        world.setBlockState(new BlockPos(i + 3, j + 6, k + 6), Blocks.COBBLESTONE.getDefaultState());
        world.setBlockState(new BlockPos(i + 3, j + 6, k + 7), Blocks.COBBLESTONE.getDefaultState());
        world.setBlockState(new BlockPos(i + 3, j + 6, k + 8), Blocks.COBBLESTONE.getDefaultState());
        world.setBlockState(new BlockPos(i + 3, j + 6, k + 9), Blocks.COBBLESTONE.getDefaultState());
        world.setBlockState(new BlockPos(i + 3, j + 6, k + 10), Blocks.COBBLESTONE.getDefaultState());
        world.setBlockState(new BlockPos(i + 3, j + 6, k + 11), Blocks.COBBLESTONE.getDefaultState());
        world.setBlockState(new BlockPos(i + 3, j + 6, k + 12), Blocks.COBBLESTONE.getDefaultState());
        world.setBlockState(new BlockPos(i + 3, j + 6, k + 13), Blocks.MOSSY_COBBLESTONE.getDefaultState());
        world.setBlockState(new BlockPos(i + 3, j + 6, k + 14), Blocks.COBBLESTONE.getDefaultState());
        world.setBlockState(new BlockPos(i + 3, j + 6, k + 15), Blocks.COBBLESTONE.getDefaultState());
        world.setBlockState(new BlockPos(i + 3, j + 7, k + 3), Blocks.COBBLESTONE.getDefaultState());
        world.setBlockState(new BlockPos(i + 3, j + 7, k + 4), Blocks.COBBLESTONE.getDefaultState());
        world.setBlockState(new BlockPos(i + 3, j + 7, k + 5), Blocks.COBBLESTONE.getDefaultState());
        world.setBlockState(new BlockPos(i + 3, j + 7, k + 6), Blocks.COBBLESTONE.getDefaultState());
        world.setBlockState(new BlockPos(i + 3, j + 7, k + 7), Blocks.COBBLESTONE.getDefaultState());
        world.setBlockState(new BlockPos(i + 3, j + 7, k + 8), Blocks.COBBLESTONE.getDefaultState());
        world.setBlockState(new BlockPos(i + 3, j + 7, k + 9), Blocks.COBBLESTONE.getDefaultState());
        world.setBlockState(new BlockPos(i + 3, j + 7, k + 10), Blocks.COBBLESTONE.getDefaultState());
        world.setBlockState(new BlockPos(i + 3, j + 7, k + 11), Blocks.MOSSY_COBBLESTONE.getDefaultState());
        world.setBlockState(new BlockPos(i + 3, j + 7, k + 12), Blocks.COBBLESTONE.getDefaultState());
        world.setBlockState(new BlockPos(i + 3, j + 7, k + 13), Blocks.COBBLESTONE.getDefaultState());
        world.setBlockState(new BlockPos(i + 3, j + 7, k + 14), Blocks.COBBLESTONE.getDefaultState());
        world.setBlockState(new BlockPos(i + 3, j + 7, k + 15), Blocks.COBBLESTONE.getDefaultState());
        world.setBlockState(new BlockPos(i + 3, j + 8, k + 1), Blocks.DIRT.getDefaultState());
        world.setBlockState(new BlockPos(i + 3, j + 8, k + 2), Blocks.DIRT.getDefaultState());
        world.setBlockState(new BlockPos(i + 3, j + 8, k + 3), Blocks.COBBLESTONE.getDefaultState());
        world.setBlockState(new BlockPos(i + 3, j + 8, k + 4), Blocks.COBBLESTONE.getDefaultState());
        world.setBlockState(new BlockPos(i + 3, j + 8, k + 5), Blocks.COBBLESTONE.getDefaultState());
        world.setBlockState(new BlockPos(i + 3, j + 8, k + 6), Blocks.COBBLESTONE.getDefaultState());
        world.setBlockState(new BlockPos(i + 3, j + 8, k + 7), Blocks.MOSSY_COBBLESTONE.getDefaultState());
        world.setBlockState(new BlockPos(i + 3, j + 8, k + 8), Blocks.COBBLESTONE.getDefaultState());
        world.setBlockState(new BlockPos(i + 3, j + 8, k + 9), Blocks.COBBLESTONE.getDefaultState());
        world.setBlockState(new BlockPos(i + 3, j + 8, k + 10), Blocks.COBBLESTONE.getDefaultState());
        world.setBlockState(new BlockPos(i + 3, j + 8, k + 11), Blocks.COBBLESTONE.getDefaultState());
        world.setBlockState(new BlockPos(i + 3, j + 8, k + 12), Blocks.COBBLESTONE.getDefaultState());
        world.setBlockState(new BlockPos(i + 3, j + 8, k + 13), Blocks.COBBLESTONE.getDefaultState());
        world.setBlockState(new BlockPos(i + 3, j + 8, k + 14), Blocks.COBBLESTONE.getDefaultState());
        world.setBlockState(new BlockPos(i + 3, j + 8, k + 15), Blocks.COBBLESTONE.getDefaultState());
        world.setBlockState(new BlockPos(i + 3, j + 8, k + 16), Blocks.DIRT.getDefaultState());
        world.setBlockState(new BlockPos(i + 3, j + 8, k + 17), Blocks.DIRT.getDefaultState());
        world.setBlockState(new BlockPos(i + 3, j + 9, k + 1), Blocks.GRASS.getDefaultState());
        world.setBlockState(new BlockPos(i + 3, j + 9, k + 2), Blocks.DIRT.getDefaultState());
        world.setBlockState(new BlockPos(i + 3, j + 9, k + 3), Blocks.COBBLESTONE.getDefaultState());
        world.setBlockState(new BlockPos(i + 3, j + 9, k + 4), Blocks.COBBLESTONE.getDefaultState());
        world.setBlockState(new BlockPos(i + 3, j + 9, k + 5), Blocks.COBBLESTONE.getDefaultState());
        world.setBlockState(new BlockPos(i + 3, j + 9, k + 6), Blocks.COBBLESTONE.getDefaultState());
        world.setBlockState(new BlockPos(i + 3, j + 9, k + 7), Blocks.COBBLESTONE.getDefaultState());
        world.setBlockState(new BlockPos(i + 3, j + 9, k + 8), Blocks.COBBLESTONE.getDefaultState());
        world.setBlockState(new BlockPos(i + 3, j + 9, k + 9), Blocks.IRON_BARS.getDefaultState());
        world.setBlockState(new BlockPos(i + 3, j + 9, k + 10), Blocks.COBBLESTONE.getDefaultState());
        world.setBlockState(new BlockPos(i + 3, j + 9, k + 11), Blocks.COBBLESTONE.getDefaultState());
        world.setBlockState(new BlockPos(i + 3, j + 9, k + 12), Blocks.MOSSY_COBBLESTONE.getDefaultState());
        world.setBlockState(new BlockPos(i + 3, j + 9, k + 13), Blocks.COBBLESTONE.getDefaultState());
        world.setBlockState(new BlockPos(i + 3, j + 9, k + 14), Blocks.COBBLESTONE.getDefaultState());
        world.setBlockState(new BlockPos(i + 3, j + 9, k + 15), Blocks.COBBLESTONE.getDefaultState());
        world.setBlockState(new BlockPos(i + 3, j + 9, k + 16), Blocks.DIRT.getDefaultState());
        world.setBlockState(new BlockPos(i + 3, j + 9, k + 17), Blocks.GRASS.getDefaultState());
        world.setBlockState(new BlockPos(i + 3, j + 10, k + 2), Blocks.GRASS.getDefaultState());
        world.setBlockState(new BlockPos(i + 3, j + 10, k + 3), Blocks.COBBLESTONE.getDefaultState());
        world.setBlockState(new BlockPos(i + 3, j + 10, k + 4), Blocks.MOSSY_COBBLESTONE.getDefaultState());
        world.setBlockState(new BlockPos(i + 3, j + 10, k + 5), Blocks.MOSSY_COBBLESTONE.getDefaultState());
        world.setBlockState(new BlockPos(i + 3, j + 10, k + 6), Blocks.COBBLESTONE.getDefaultState());
        world.setBlockState(new BlockPos(i + 3, j + 10, k + 7), Blocks.MOSSY_COBBLESTONE.getDefaultState());
        world.setBlockState(new BlockPos(i + 3, j + 10, k + 8), Blocks.COBBLESTONE.getDefaultState());
        world.setBlockState(new BlockPos(i + 3, j + 10, k + 9), Blocks.IRON_BARS.getDefaultState());
        world.setBlockState(new BlockPos(i + 3, j + 10, k + 10), Blocks.COBBLESTONE.getDefaultState());
        world.setBlockState(new BlockPos(i + 3, j + 10, k + 11), Blocks.COBBLESTONE.getDefaultState());
        world.setBlockState(new BlockPos(i + 3, j + 10, k + 12), Blocks.COBBLESTONE.getDefaultState());
        world.setBlockState(new BlockPos(i + 3, j + 10, k + 13), Blocks.COBBLESTONE.getDefaultState());
        world.setBlockState(new BlockPos(i + 3, j + 10, k + 14), Blocks.COBBLESTONE.getDefaultState());
        world.setBlockState(new BlockPos(i + 3, j + 10, k + 15), Blocks.COBBLESTONE.getDefaultState());
        world.setBlockState(new BlockPos(i + 3, j + 10, k + 16), Blocks.GRASS.getDefaultState());
        world.setBlockState(new BlockPos(i + 3, j + 11, k + 3), Blocks.GRASS.getDefaultState());
        world.setBlockState(new BlockPos(i + 3, j + 11, k + 4), Blocks.DIRT.getDefaultState());
        world.setBlockState(new BlockPos(i + 3, j + 11, k + 5), Blocks.COBBLESTONE.getDefaultState());
        world.setBlockState(new BlockPos(i + 3, j + 11, k + 6), Blocks.COBBLESTONE.getDefaultState());
        world.setBlockState(new BlockPos(i + 3, j + 11, k + 7), Blocks.COBBLESTONE.getDefaultState());
        world.setBlockState(new BlockPos(i + 3, j + 11, k + 8), Blocks.COBBLESTONE.getDefaultState());
        world.setBlockState(new BlockPos(i + 3, j + 11, k + 9), Blocks.MOSSY_COBBLESTONE.getDefaultState());
        world.setBlockState(new BlockPos(i + 3, j + 11, k + 10), Blocks.COBBLESTONE.getDefaultState());
        world.setBlockState(new BlockPos(i + 3, j + 11, k + 11), Blocks.COBBLESTONE.getDefaultState());
        world.setBlockState(new BlockPos(i + 3, j + 11, k + 12), Blocks.COBBLESTONE.getDefaultState());
        world.setBlockState(new BlockPos(i + 3, j + 11, k + 13), Blocks.COBBLESTONE.getDefaultState());
        world.setBlockState(new BlockPos(i + 3, j + 11, k + 14), Blocks.DIRT.getDefaultState());
        world.setBlockState(new BlockPos(i + 3, j + 11, k + 15), Blocks.GRASS.getDefaultState());
        world.setBlockState(new BlockPos(i + 3, j + 12, k + 4), Blocks.GRASS.getDefaultState());
        world.setBlockState(new BlockPos(i + 3, j + 12, k + 5), Blocks.GRASS.getDefaultState());
        world.setBlockState(new BlockPos(i + 3, j + 12, k + 6), Blocks.GRASS.getDefaultState());
        world.setBlockState(new BlockPos(i + 3, j + 12, k + 7), Blocks.GRASS.getDefaultState());
        world.setBlockState(new BlockPos(i + 3, j + 12, k + 8), Blocks.GRASS.getDefaultState());
        world.setBlockState(new BlockPos(i + 3, j + 12, k + 9), Blocks.GRASS.getDefaultState());
        world.setBlockState(new BlockPos(i + 3, j + 12, k + 10), Blocks.GRASS.getDefaultState());
        world.setBlockState(new BlockPos(i + 3, j + 12, k + 11), Blocks.GRASS.getDefaultState());
        world.setBlockState(new BlockPos(i + 3, j + 12, k + 12), Blocks.GRASS.getDefaultState());
        world.setBlockState(new BlockPos(i + 3, j + 12, k + 13), Blocks.GRASS.getDefaultState());
        world.setBlockState(new BlockPos(i + 3, j + 12, k + 14), Blocks.GRASS.getDefaultState());
        world.setBlockState(new BlockPos(i + 4, j + 4, k + 3), Blocks.COBBLESTONE.getDefaultState());
        world.setBlockState(new BlockPos(i + 4, j + 4, k + 4), Blocks.COBBLESTONE.getDefaultState());
        world.setBlockState(new BlockPos(i + 4, j + 4, k + 5), Blocks.COBBLESTONE.getDefaultState());
        world.setBlockState(new BlockPos(i + 4, j + 4, k + 6), Blocks.COBBLESTONE.getDefaultState());
        world.setBlockState(new BlockPos(i + 4, j + 4, k + 7), Blocks.COBBLESTONE.getDefaultState());
        world.setBlockState(new BlockPos(i + 4, j + 4, k + 8), Blocks.COBBLESTONE.getDefaultState());
        world.setBlockState(new BlockPos(i + 4, j + 4, k + 9), Blocks.COBBLESTONE.getDefaultState());
        world.setBlockState(new BlockPos(i + 4, j + 4, k + 10), Blocks.COBBLESTONE.getDefaultState());
        world.setBlockState(new BlockPos(i + 4, j + 4, k + 11), Blocks.COBBLESTONE.getDefaultState());
        world.setBlockState(new BlockPos(i + 4, j + 4, k + 12), Blocks.COBBLESTONE.getDefaultState());
        world.setBlockState(new BlockPos(i + 4, j + 4, k + 13), Blocks.COBBLESTONE.getDefaultState());
        world.setBlockState(new BlockPos(i + 4, j + 4, k + 14), Blocks.COBBLESTONE.getDefaultState());
        world.setBlockState(new BlockPos(i + 4, j + 4, k + 15), Blocks.COBBLESTONE.getDefaultState());
        world.setBlockState(new BlockPos(i + 4, j + 5, k + 3), Blocks.COBBLESTONE.getDefaultState());
        world.setBlockState(new BlockPos(i + 4, j + 5, k + 15), Blocks.COBBLESTONE.getDefaultState());
        world.setBlockState(new BlockPos(i + 4, j + 6, k + 3), Blocks.COBBLESTONE.getDefaultState());
        world.setBlockState(new BlockPos(i + 4, j + 6, k + 15), Blocks.COBBLESTONE.getDefaultState());
        world.setBlockState(new BlockPos(i + 4, j + 7, k + 3), Blocks.MOSSY_COBBLESTONE.getDefaultState());
        world.setBlockState(new BlockPos(i + 4, j + 7, k + 15), Blocks.COBBLESTONE.getDefaultState());
        world.setBlockState(new BlockPos(i + 4, j + 8, k + 0), Blocks.DIRT.getDefaultState());
        world.setBlockState(new BlockPos(i + 4, j + 8, k + 1), Blocks.DIRT.getDefaultState());
        world.setBlockState(new BlockPos(i + 4, j + 8, k + 2), Blocks.DIRT.getDefaultState());
        world.setBlockState(new BlockPos(i + 4, j + 8, k + 3), Blocks.COBBLESTONE.getDefaultState());
        world.setBlockState(new BlockPos(i + 4, j + 8, k + 4), Blocks.MOSSY_COBBLESTONE.getDefaultState());
        world.setBlockState(new BlockPos(i + 4, j + 8, k + 5), Blocks.MOSSY_COBBLESTONE.getDefaultState());
        world.setBlockState(new BlockPos(i + 4, j + 8, k + 6), Blocks.COBBLESTONE.getDefaultState());
        world.setBlockState(new BlockPos(i + 4, j + 8, k + 7), Blocks.COBBLESTONE.getDefaultState());
        world.setBlockState(new BlockPos(i + 4, j + 8, k + 8), Blocks.COBBLESTONE.getDefaultState());
        world.setBlockState(new BlockPos(i + 4, j + 8, k + 9), Blocks.MOSSY_COBBLESTONE.getDefaultState());
        world.setBlockState(new BlockPos(i + 4, j + 8, k + 10), Blocks.MOSSY_COBBLESTONE.getDefaultState());
        world.setBlockState(new BlockPos(i + 4, j + 8, k + 11), Blocks.COBBLESTONE.getDefaultState());
        world.setBlockState(new BlockPos(i + 4, j + 8, k + 12), Blocks.COBBLESTONE.getDefaultState());
        world.setBlockState(new BlockPos(i + 4, j + 8, k + 13), Blocks.COBBLESTONE.getDefaultState());
        world.setBlockState(new BlockPos(i + 4, j + 8, k + 14), Blocks.COBBLESTONE.getDefaultState());
        world.setBlockState(new BlockPos(i + 4, j + 8, k + 15), Blocks.COBBLESTONE.getDefaultState());
        world.setBlockState(new BlockPos(i + 4, j + 8, k + 16), Blocks.DIRT.getDefaultState());
        world.setBlockState(new BlockPos(i + 4, j + 8, k + 17), Blocks.DIRT.getDefaultState());
        world.setBlockState(new BlockPos(i + 4, j + 8, k + 18), Blocks.DIRT.getDefaultState());
        world.setBlockState(new BlockPos(i + 4, j + 9, k + 0), Blocks.GRASS.getDefaultState());
        world.setBlockState(new BlockPos(i + 4, j + 9, k + 1), Blocks.DIRT.getDefaultState());
        world.setBlockState(new BlockPos(i + 4, j + 9, k + 2), Blocks.DIRT.getDefaultState());
        world.setBlockState(new BlockPos(i + 4, j + 9, k + 3), Blocks.COBBLESTONE.getDefaultState());
        world.setBlockState(new BlockPos(i + 4, j + 9, k + 15), Blocks.COBBLESTONE.getDefaultState());
        world.setBlockState(new BlockPos(i + 4, j + 9, k + 16), Blocks.DIRT.getDefaultState());
        world.setBlockState(new BlockPos(i + 4, j + 9, k + 17), Blocks.DIRT.getDefaultState());
        world.setBlockState(new BlockPos(i + 4, j + 9, k + 18), Blocks.GRASS.getDefaultState());
        world.setBlockState(new BlockPos(i + 4, j + 10, k + 1), Blocks.GRASS.getDefaultState());
        world.setBlockState(new BlockPos(i + 4, j + 10, k + 2), Blocks.DIRT.getDefaultState());
        world.setBlockState(new BlockPos(i + 4, j + 10, k + 3), Blocks.COBBLESTONE.getDefaultState());
        world.setBlockState(new BlockPos(i + 4, j + 10, k + 15), Blocks.MOSSY_COBBLESTONE.getDefaultState());
        world.setBlockState(new BlockPos(i + 4, j + 10, k + 16), Blocks.DIRT.getDefaultState());
        world.setBlockState(new BlockPos(i + 4, j + 10, k + 17), Blocks.GRASS.getDefaultState());
        world.setBlockState(new BlockPos(i + 4, j + 11, k + 2), Blocks.GRASS.getDefaultState());
        world.setBlockState(new BlockPos(i + 4, j + 11, k + 3), Blocks.DIRT.getDefaultState());
        world.setBlockState(new BlockPos(i + 4, j + 11, k + 4), Blocks.COBBLESTONE.getDefaultState());
        world.setBlockState(new BlockPos(i + 4, j + 11, k + 14), Blocks.MOSSY_COBBLESTONE.getDefaultState());
        world.setBlockState(new BlockPos(i + 4, j + 11, k + 15), Blocks.DIRT.getDefaultState());
        world.setBlockState(new BlockPos(i + 4, j + 11, k + 16), Blocks.GRASS.getDefaultState());
        world.setBlockState(new BlockPos(i + 4, j + 12, k + 3), Blocks.GRASS.getDefaultState());
        world.setBlockState(new BlockPos(i + 4, j + 12, k + 4), Blocks.GRASS.getDefaultState());
        world.setBlockState(new BlockPos(i + 4, j + 12, k + 5), Blocks.COBBLESTONE.getDefaultState());
        world.setBlockState(new BlockPos(i + 4, j + 12, k + 6), Blocks.COBBLESTONE.getDefaultState());
        world.setBlockState(new BlockPos(i + 4, j + 12, k + 7), Blocks.COBBLESTONE.getDefaultState());
        world.setBlockState(new BlockPos(i + 4, j + 12, k + 8), Blocks.COBBLESTONE.getDefaultState());
        world.setBlockState(new BlockPos(i + 4, j + 12, k + 9), Blocks.COBBLESTONE.getDefaultState());
        world.setBlockState(new BlockPos(i + 4, j + 12, k + 10), Blocks.COBBLESTONE.getDefaultState());
        world.setBlockState(new BlockPos(i + 4, j + 12, k + 11), Blocks.COBBLESTONE.getDefaultState());
        world.setBlockState(new BlockPos(i + 4, j + 12, k + 12), Blocks.COBBLESTONE.getDefaultState());
        world.setBlockState(new BlockPos(i + 4, j + 12, k + 13), Blocks.COBBLESTONE.getDefaultState());
        world.setBlockState(new BlockPos(i + 4, j + 12, k + 14), Blocks.DIRT.getDefaultState());
        world.setBlockState(new BlockPos(i + 4, j + 12, k + 15), Blocks.GRASS.getDefaultState());
        world.setBlockState(new BlockPos(i + 4, j + 13, k + 5), Blocks.GRASS.getDefaultState());
        world.setBlockState(new BlockPos(i + 4, j + 13, k + 6), Blocks.GRASS.getDefaultState());
        world.setBlockState(new BlockPos(i + 4, j + 13, k + 7), Blocks.GRASS.getDefaultState());
        world.setBlockState(new BlockPos(i + 4, j + 13, k + 8), Blocks.GRASS.getDefaultState());
        world.setBlockState(new BlockPos(i + 4, j + 13, k + 9), Blocks.GRASS.getDefaultState());
        world.setBlockState(new BlockPos(i + 4, j + 13, k + 10), Blocks.GRASS.getDefaultState());
        world.setBlockState(new BlockPos(i + 4, j + 13, k + 11), Blocks.GRASS.getDefaultState());
        world.setBlockState(new BlockPos(i + 4, j + 13, k + 12), Blocks.GRASS.getDefaultState());
        world.setBlockState(new BlockPos(i + 4, j + 13, k + 13), Blocks.GRASS.getDefaultState());
        world.setBlockState(new BlockPos(i + 4, j + 13, k + 14), Blocks.GRASS.getDefaultState());
        world.setBlockState(new BlockPos(i + 5, j + 4, k + 3), Blocks.COBBLESTONE.getDefaultState());
        world.setBlockState(new BlockPos(i + 5, j + 4, k + 4), Blocks.COBBLESTONE.getDefaultState());
        world.setBlockState(new BlockPos(i + 5, j + 4, k + 5), Blocks.COBBLESTONE.getDefaultState());
        world.setBlockState(new BlockPos(i + 5, j + 4, k + 6), Blocks.COBBLESTONE.getDefaultState());
        world.setBlockState(new BlockPos(i + 5, j + 4, k + 7), Blocks.COBBLESTONE.getDefaultState());
        world.setBlockState(new BlockPos(i + 5, j + 4, k + 8), Blocks.COBBLESTONE.getDefaultState());
        world.setBlockState(new BlockPos(i + 5, j + 4, k + 9), Blocks.COBBLESTONE.getDefaultState());
        world.setBlockState(new BlockPos(i + 5, j + 4, k + 10), Blocks.MOSSY_COBBLESTONE.getDefaultState());
        world.setBlockState(new BlockPos(i + 5, j + 4, k + 11), Blocks.COBBLESTONE.getDefaultState());
        world.setBlockState(new BlockPos(i + 5, j + 4, k + 12), Blocks.COBBLESTONE.getDefaultState());
        world.setBlockState(new BlockPos(i + 5, j + 4, k + 13), Blocks.MOSSY_COBBLESTONE.getDefaultState());
        world.setBlockState(new BlockPos(i + 5, j + 4, k + 14), Blocks.COBBLESTONE.getDefaultState());
        world.setBlockState(new BlockPos(i + 5, j + 4, k + 15), Blocks.COBBLESTONE.getDefaultState());
        world.setBlockState(new BlockPos(i + 5, j + 5, k + 3), Blocks.COBBLESTONE.getDefaultState());
        world.setBlockState(new BlockPos(i + 5, j + 5, k + 15), Blocks.COBBLESTONE.getDefaultState());
        world.setBlockState(new BlockPos(i + 5, j + 6, k + 3), Blocks.MOSSY_COBBLESTONE.getDefaultState());
        world.setBlockState(new BlockPos(i + 5, j + 6, k + 15), Blocks.COBBLESTONE.getDefaultState());
        world.setBlockState(new BlockPos(i + 5, j + 7, k + 3), Blocks.COBBLESTONE.getDefaultState());
        world.setBlockState(new BlockPos(i + 5, j + 7, k + 15), Blocks.COBBLESTONE.getDefaultState());
        world.setBlockState(new BlockPos(i + 5, j + 8, k + 0), Blocks.DIRT.getDefaultState());
        world.setBlockState(new BlockPos(i + 5, j + 8, k + 1), Blocks.DIRT.getDefaultState());
        world.setBlockState(new BlockPos(i + 5, j + 8, k + 2), Blocks.DIRT.getDefaultState());
        world.setBlockState(new BlockPos(i + 5, j + 8, k + 3), Blocks.COBBLESTONE.getDefaultState());
        world.setBlockState(new BlockPos(i + 5, j + 8, k + 4), Blocks.MOSSY_COBBLESTONE.getDefaultState());
        world.setBlockState(new BlockPos(i + 5, j + 8, k + 5), Blocks.COBBLESTONE.getDefaultState());
        world.setBlockState(new BlockPos(i + 5, j + 8, k + 6), Blocks.COBBLESTONE.getDefaultState());
        world.setBlockState(new BlockPos(i + 5, j + 8, k + 7), Blocks.COBBLESTONE.getDefaultState());
        world.setBlockState(new BlockPos(i + 5, j + 8, k + 8), Blocks.COBBLESTONE.getDefaultState());
        world.setBlockState(new BlockPos(i + 5, j + 8, k + 9), Blocks.COBBLESTONE.getDefaultState());
        world.setBlockState(new BlockPos(i + 5, j + 8, k + 10), Blocks.COBBLESTONE.getDefaultState());
        world.setBlockState(new BlockPos(i + 5, j + 8, k + 11), Blocks.COBBLESTONE.getDefaultState());
        world.setBlockState(new BlockPos(i + 5, j + 8, k + 12), Blocks.COBBLESTONE.getDefaultState());
        world.setBlockState(new BlockPos(i + 5, j + 8, k + 13), Blocks.MOSSY_COBBLESTONE.getDefaultState());
        world.setBlockState(new BlockPos(i + 5, j + 8, k + 14), Blocks.COBBLESTONE.getDefaultState());
        world.setBlockState(new BlockPos(i + 5, j + 8, k + 15), Blocks.COBBLESTONE.getDefaultState());
        world.setBlockState(new BlockPos(i + 5, j + 8, k + 16), Blocks.DIRT.getDefaultState());
        world.setBlockState(new BlockPos(i + 5, j + 8, k + 17), Blocks.DIRT.getDefaultState());
        world.setBlockState(new BlockPos(i + 5, j + 8, k + 18), Blocks.DIRT.getDefaultState());
        world.setBlockState(new BlockPos(i + 5, j + 9, k + 0), Blocks.GRASS.getDefaultState());
        world.setBlockState(new BlockPos(i + 5, j + 9, k + 1), Blocks.DIRT.getDefaultState());
        world.setBlockState(new BlockPos(i + 5, j + 9, k + 2), Blocks.DIRT.getDefaultState());
        world.setBlockState(new BlockPos(i + 5, j + 9, k + 3), Blocks.COBBLESTONE.getDefaultState());
        world.setBlockState(new BlockPos(i + 5, j + 9, k + 15), Blocks.COBBLESTONE.getDefaultState());
        world.setBlockState(new BlockPos(i + 5, j + 9, k + 16), Blocks.DIRT.getDefaultState());
        world.setBlockState(new BlockPos(i + 5, j + 9, k + 17), Blocks.DIRT.getDefaultState());
        world.setBlockState(new BlockPos(i + 5, j + 9, k + 18), Blocks.GRASS.getDefaultState());
        world.setBlockState(new BlockPos(i + 5, j + 10, k + 1), Blocks.GRASS.getDefaultState());
        world.setBlockState(new BlockPos(i + 5, j + 10, k + 2), Blocks.DIRT.getDefaultState());
        world.setBlockState(new BlockPos(i + 5, j + 10, k + 3), Blocks.COBBLESTONE.getDefaultState());
        world.setBlockState(new BlockPos(i + 5, j + 10, k + 15), Blocks.COBBLESTONE.getDefaultState());
        world.setBlockState(new BlockPos(i + 5, j + 10, k + 16), Blocks.DIRT.getDefaultState());
        world.setBlockState(new BlockPos(i + 5, j + 10, k + 17), Blocks.GRASS.getDefaultState());
        world.setBlockState(new BlockPos(i + 5, j + 11, k + 2), Blocks.DIRT.getDefaultState());
        world.setBlockState(new BlockPos(i + 5, j + 11, k + 3), Blocks.COBBLESTONE.getDefaultState());
        world.setBlockState(new BlockPos(i + 5, j + 11, k + 6), Blocks.STONE_STAIRS.getStateFromMeta(4));
        world.setBlockState(new BlockPos(i + 5, j + 11, k + 12), Blocks.STONE_STAIRS.getStateFromMeta(4));
        world.setBlockState(new BlockPos(i + 5, j + 11, k + 15), Blocks.COBBLESTONE.getDefaultState());
        world.setBlockState(new BlockPos(i + 5, j + 11, k + 16), Blocks.GRASS.getDefaultState());
        world.setBlockState(new BlockPos(i + 5, j + 12, k + 2), Blocks.GRASS.getDefaultState());
        world.setBlockState(new BlockPos(i + 5, j + 12, k + 3), Blocks.GRASS.getDefaultState());
        world.setBlockState(new BlockPos(i + 5, j + 12, k + 4), Blocks.COBBLESTONE.getDefaultState());
        world.setBlockState(new BlockPos(i + 5, j + 12, k + 5), Blocks.COBBLESTONE.getDefaultState());
        world.setBlockState(new BlockPos(i + 5, j + 12, k + 6), Blocks.COBBLESTONE.getDefaultState());
        world.setBlockState(new BlockPos(i + 5, j + 12, k + 7), Blocks.COBBLESTONE.getDefaultState());
        world.setBlockState(new BlockPos(i + 5, j + 12, k + 8), Blocks.COBBLESTONE.getDefaultState());
        world.setBlockState(new BlockPos(i + 5, j + 12, k + 9), Blocks.COBBLESTONE.getDefaultState());
        world.setBlockState(new BlockPos(i + 5, j + 12, k + 10), Blocks.COBBLESTONE.getDefaultState());
        world.setBlockState(new BlockPos(i + 5, j + 12, k + 11), Blocks.COBBLESTONE.getDefaultState());
        world.setBlockState(new BlockPos(i + 5, j + 12, k + 12), Blocks.MOSSY_COBBLESTONE.getDefaultState());
        world.setBlockState(new BlockPos(i + 5, j + 12, k + 13), Blocks.COBBLESTONE.getDefaultState());
        world.setBlockState(new BlockPos(i + 5, j + 12, k + 14), Blocks.COBBLESTONE.getDefaultState());
        world.setBlockState(new BlockPos(i + 5, j + 12, k + 15), Blocks.DIRT.getDefaultState());
        world.setBlockState(new BlockPos(i + 5, j + 13, k + 4), Blocks.GRASS.getDefaultState());
        world.setBlockState(new BlockPos(i + 5, j + 13, k + 5), Blocks.GRASS.getDefaultState());
        world.setBlockState(new BlockPos(i + 5, j + 13, k + 6), Blocks.GRASS.getDefaultState());
        world.setBlockState(new BlockPos(i + 5, j + 13, k + 7), Blocks.GRASS.getDefaultState());
        world.setBlockState(new BlockPos(i + 5, j + 13, k + 8), Blocks.GRASS.getDefaultState());
        world.setBlockState(new BlockPos(i + 5, j + 13, k + 9), Blocks.GRASS.getDefaultState());
        world.setBlockState(new BlockPos(i + 5, j + 13, k + 10), Blocks.GRASS.getDefaultState());
        world.setBlockState(new BlockPos(i + 5, j + 13, k + 11), Blocks.GRASS.getDefaultState());
        world.setBlockState(new BlockPos(i + 5, j + 13, k + 12), Blocks.GRASS.getDefaultState());
        world.setBlockState(new BlockPos(i + 5, j + 13, k + 13), Blocks.GRASS.getDefaultState());
        world.setBlockState(new BlockPos(i + 5, j + 13, k + 14), Blocks.GRASS.getDefaultState());
        world.setBlockState(new BlockPos(i + 5, j + 13, k + 15), Blocks.GRASS.getDefaultState());
        world.setBlockState(new BlockPos(i + 6, j + 0, k + 6), Blocks.COBBLESTONE.getDefaultState());
        world.setBlockState(new BlockPos(i + 6, j + 0, k + 7), Blocks.COBBLESTONE.getDefaultState());
        world.setBlockState(new BlockPos(i + 6, j + 0, k + 8), Blocks.COBBLESTONE.getDefaultState());
        world.setBlockState(new BlockPos(i + 6, j + 0, k + 9), Blocks.COBBLESTONE.getDefaultState());
        world.setBlockState(new BlockPos(i + 6, j + 0, k + 10), Blocks.COBBLESTONE.getDefaultState());
        world.setBlockState(new BlockPos(i + 6, j + 0, k + 11), Blocks.COBBLESTONE.getDefaultState());
        world.setBlockState(new BlockPos(i + 6, j + 0, k + 12), Blocks.COBBLESTONE.getDefaultState());
        world.setBlockState(new BlockPos(i + 6, j + 1, k + 6), Blocks.MOSSY_COBBLESTONE.getDefaultState());
        world.setBlockState(new BlockPos(i + 6, j + 1, k + 7), Blocks.COBBLESTONE.getDefaultState());
        world.setBlockState(new BlockPos(i + 6, j + 1, k + 8), Blocks.COBBLESTONE.getDefaultState());
        world.setBlockState(new BlockPos(i + 6, j + 1, k + 9), Blocks.MOSSY_COBBLESTONE.getDefaultState());
        world.setBlockState(new BlockPos(i + 6, j + 1, k + 10), Blocks.MOSSY_COBBLESTONE.getDefaultState());
        world.setBlockState(new BlockPos(i + 6, j + 1, k + 11), Blocks.COBBLESTONE.getDefaultState());
        world.setBlockState(new BlockPos(i + 6, j + 1, k + 12), Blocks.COBBLESTONE.getDefaultState());
        world.setBlockState(new BlockPos(i + 6, j + 2, k + 6), Blocks.COBBLESTONE.getDefaultState());
        world.setBlockState(new BlockPos(i + 6, j + 2, k + 7), Blocks.COBBLESTONE.getDefaultState());
        world.setBlockState(new BlockPos(i + 6, j + 2, k + 8), Blocks.COBBLESTONE.getDefaultState());
        world.setBlockState(new BlockPos(i + 6, j + 2, k + 9), Blocks.COBBLESTONE.getDefaultState());
        world.setBlockState(new BlockPos(i + 6, j + 2, k + 10), Blocks.COBBLESTONE.getDefaultState());
        world.setBlockState(new BlockPos(i + 6, j + 2, k + 11), Blocks.COBBLESTONE.getDefaultState());
        world.setBlockState(new BlockPos(i + 6, j + 2, k + 12), Blocks.COBBLESTONE.getDefaultState());
        world.setBlockState(new BlockPos(i + 6, j + 3, k + 6), Blocks.COBBLESTONE.getDefaultState());
        world.setBlockState(new BlockPos(i + 6, j + 3, k + 7), Blocks.COBBLESTONE.getDefaultState());
        world.setBlockState(new BlockPos(i + 6, j + 3, k + 8), Blocks.MOSSY_COBBLESTONE.getDefaultState());
        world.setBlockState(new BlockPos(i + 6, j + 3, k + 9), Blocks.COBBLESTONE.getDefaultState());
        world.setBlockState(new BlockPos(i + 6, j + 3, k + 10), Blocks.COBBLESTONE.getDefaultState());
        world.setBlockState(new BlockPos(i + 6, j + 3, k + 11), Blocks.COBBLESTONE.getDefaultState());
        world.setBlockState(new BlockPos(i + 6, j + 3, k + 12), Blocks.COBBLESTONE.getDefaultState());
        world.setBlockState(new BlockPos(i + 6, j + 4, k + 3), Blocks.COBBLESTONE.getDefaultState());
        world.setBlockState(new BlockPos(i + 6, j + 4, k + 4), Blocks.COBBLESTONE.getDefaultState());
        world.setBlockState(new BlockPos(i + 6, j + 4, k + 5), Blocks.COBBLESTONE.getDefaultState());
        world.setBlockState(new BlockPos(i + 6, j + 4, k + 6), Blocks.COBBLESTONE.getDefaultState());
        world.setBlockState(new BlockPos(i + 6, j + 4, k + 7), Blocks.STONE_STAIRS.getStateFromMeta(1));
        world.setBlockState(new BlockPos(i + 6, j + 4, k + 8), Blocks.STONE_STAIRS.getStateFromMeta(1));
        world.setBlockState(new BlockPos(i + 6, j + 4, k + 9), Blocks.COBBLESTONE.getDefaultState());
        world.setBlockState(new BlockPos(i + 6, j + 4, k + 10), Blocks.STONE_STAIRS.getStateFromMeta(1));
        world.setBlockState(new BlockPos(i + 6, j + 4, k + 11), Blocks.STONE_STAIRS.getStateFromMeta(1));
        world.setBlockState(new BlockPos(i + 6, j + 4, k + 12), Blocks.COBBLESTONE.getDefaultState());
        world.setBlockState(new BlockPos(i + 6, j + 4, k + 13), Blocks.COBBLESTONE.getDefaultState());
        world.setBlockState(new BlockPos(i + 6, j + 4, k + 14), Blocks.COBBLESTONE.getDefaultState());
        world.setBlockState(new BlockPos(i + 6, j + 4, k + 15), Blocks.COBBLESTONE.getDefaultState());
        world.setBlockState(new BlockPos(i + 6, j + 5, k + 3), Blocks.COBBLESTONE.getDefaultState());
        world.setBlockState(new BlockPos(i + 6, j + 5, k + 6), Blocks.MOSSY_COBBLESTONE.getDefaultState());
        world.setBlockState(new BlockPos(i + 6, j + 5, k + 12), Blocks.COBBLESTONE.getDefaultState());
        world.setBlockState(new BlockPos(i + 6, j + 5, k + 15), Blocks.MOSSY_COBBLESTONE.getDefaultState());
        world.setBlockState(new BlockPos(i + 6, j + 6, k + 3), Blocks.COBBLESTONE.getDefaultState());
        world.setBlockState(new BlockPos(i + 6, j + 6, k + 6), Blocks.MOSSY_COBBLESTONE.getDefaultState());
        world.setBlockState(new BlockPos(i + 6, j + 6, k + 12), Blocks.COBBLESTONE.getDefaultState());
        world.setBlockState(new BlockPos(i + 6, j + 6, k + 15), Blocks.COBBLESTONE.getDefaultState());
        world.setBlockState(new BlockPos(i + 6, j + 7, k + 3), Blocks.COBBLESTONE.getDefaultState());
        world.setBlockState(new BlockPos(i + 6, j + 7, k + 6), Blocks.COBBLESTONE.getDefaultState());
        world.setBlockState(new BlockPos(i + 6, j + 7, k + 12), Blocks.COBBLESTONE.getDefaultState());
        world.setBlockState(new BlockPos(i + 6, j + 7, k + 15), Blocks.COBBLESTONE.getDefaultState());
        world.setBlockState(new BlockPos(i + 6, j + 8, k + 0), Blocks.DIRT.getDefaultState());
        world.setBlockState(new BlockPos(i + 6, j + 8, k + 1), Blocks.DIRT.getDefaultState());
        world.setBlockState(new BlockPos(i + 6, j + 8, k + 2), Blocks.DIRT.getDefaultState());
        world.setBlockState(new BlockPos(i + 6, j + 8, k + 3), Blocks.COBBLESTONE.getDefaultState());
        world.setBlockState(new BlockPos(i + 6, j + 8, k + 4), Blocks.COBBLESTONE.getDefaultState());
        world.setBlockState(new BlockPos(i + 6, j + 8, k + 5), Blocks.COBBLESTONE.getDefaultState());
        world.setBlockState(new BlockPos(i + 6, j + 8, k + 6), Blocks.COBBLESTONE.getDefaultState());
        world.setBlockState(new BlockPos(i + 6, j + 8, k + 7), Blocks.STONE_STAIRS.getStateFromMeta(5));
        world.setBlockState(new BlockPos(i + 6, j + 8, k + 8), Blocks.STONE_STAIRS.getStateFromMeta(5));
        world.setBlockState(new BlockPos(i + 6, j + 8, k + 9), Blocks.STONE_STAIRS.getStateFromMeta(5));
        world.setBlockState(new BlockPos(i + 6, j + 8, k + 10), Blocks.STONE_STAIRS.getStateFromMeta(5));
        world.setBlockState(new BlockPos(i + 6, j + 8, k + 11), Blocks.STONE_STAIRS.getStateFromMeta(5));
        world.setBlockState(new BlockPos(i + 6, j + 8, k + 12), Blocks.MOSSY_COBBLESTONE.getDefaultState());
        world.setBlockState(new BlockPos(i + 6, j + 8, k + 13), Blocks.COBBLESTONE.getDefaultState());
        world.setBlockState(new BlockPos(i + 6, j + 8, k + 14), Blocks.COBBLESTONE.getDefaultState());
        world.setBlockState(new BlockPos(i + 6, j + 8, k + 15), Blocks.COBBLESTONE.getDefaultState());
        world.setBlockState(new BlockPos(i + 6, j + 8, k + 16), Blocks.DIRT.getDefaultState());
        world.setBlockState(new BlockPos(i + 6, j + 8, k + 17), Blocks.DIRT.getDefaultState());
        world.setBlockState(new BlockPos(i + 6, j + 8, k + 18), Blocks.DIRT.getDefaultState());
        world.setBlockState(new BlockPos(i + 6, j + 9, k + 0), Blocks.GRASS.getDefaultState());
        world.setBlockState(new BlockPos(i + 6, j + 9, k + 1), Blocks.DIRT.getDefaultState());
        world.setBlockState(new BlockPos(i + 6, j + 9, k + 2), Blocks.DIRT.getDefaultState());
        world.setBlockState(new BlockPos(i + 6, j + 9, k + 3), Blocks.COBBLESTONE.getDefaultState());
        world.setBlockState(new BlockPos(i + 6, j + 9, k + 6), Blocks.MOSSY_COBBLESTONE.getDefaultState());
        world.setBlockState(new BlockPos(i + 6, j + 9, k + 12), Blocks.COBBLESTONE.getDefaultState());
        world.setBlockState(new BlockPos(i + 6, j + 9, k + 15), Blocks.COBBLESTONE.getDefaultState());
        world.setBlockState(new BlockPos(i + 6, j + 9, k + 16), Blocks.DIRT.getDefaultState());
        world.setBlockState(new BlockPos(i + 6, j + 9, k + 17), Blocks.DIRT.getDefaultState());
        world.setBlockState(new BlockPos(i + 6, j + 9, k + 18), Blocks.GRASS.getDefaultState());
        world.setBlockState(new BlockPos(i + 6, j + 10, k + 1), Blocks.GRASS.getDefaultState());
        world.setBlockState(new BlockPos(i + 6, j + 10, k + 2), Blocks.DIRT.getDefaultState());
        world.setBlockState(new BlockPos(i + 6, j + 10, k + 3), Blocks.COBBLESTONE.getDefaultState());
        world.setBlockState(new BlockPos(i + 6, j + 10, k + 6), Blocks.COBBLESTONE.getDefaultState());
        world.setBlockState(new BlockPos(i + 6, j + 10, k + 12), Blocks.MOSSY_COBBLESTONE.getDefaultState());
        world.setBlockState(new BlockPos(i + 6, j + 10, k + 15), Blocks.COBBLESTONE.getDefaultState());
        world.setBlockState(new BlockPos(i + 6, j + 10, k + 16), Blocks.DIRT.getDefaultState());
        world.setBlockState(new BlockPos(i + 6, j + 10, k + 17), Blocks.GRASS.getDefaultState());
        world.setBlockState(new BlockPos(i + 6, j + 11, k + 2), Blocks.GRASS.getDefaultState());
        world.setBlockState(new BlockPos(i + 6, j + 11, k + 3), Blocks.COBBLESTONE.getDefaultState());
        world.setBlockState(new BlockPos(i + 6, j + 11, k + 5), Blocks.STONE_STAIRS.getStateFromMeta(6));
        world.setBlockState(new BlockPos(i + 6, j + 11, k + 6), Blocks.COBBLESTONE.getDefaultState());
        world.setBlockState(new BlockPos(i + 6, j + 11, k + 7), Blocks.STONE_STAIRS.getStateFromMeta(7));
        world.setBlockState(new BlockPos(i + 6, j + 11, k + 11), Blocks.STONE_STAIRS.getStateFromMeta(6));
        world.setBlockState(new BlockPos(i + 6, j + 11, k + 12), Blocks.COBBLESTONE.getDefaultState());
        world.setBlockState(new BlockPos(i + 6, j + 11, k + 13), Blocks.STONE_STAIRS.getStateFromMeta(7));
        world.setBlockState(new BlockPos(i + 6, j + 11, k + 15), Blocks.MOSSY_COBBLESTONE.getDefaultState());
        world.setBlockState(new BlockPos(i + 6, j + 11, k + 16), Blocks.GRASS.getDefaultState());
        world.setBlockState(new BlockPos(i + 6, j + 12, k + 3), Blocks.GRASS.getDefaultState());
        world.setBlockState(new BlockPos(i + 6, j + 12, k + 4), Blocks.COBBLESTONE.getDefaultState());
        world.setBlockState(new BlockPos(i + 6, j + 12, k + 5), Blocks.COBBLESTONE.getDefaultState());
        world.setBlockState(new BlockPos(i + 6, j + 12, k + 6), Blocks.MOSSY_COBBLESTONE.getDefaultState());
        world.setBlockState(new BlockPos(i + 6, j + 12, k + 7), Blocks.COBBLESTONE.getDefaultState());
        world.setBlockState(new BlockPos(i + 6, j + 12, k + 8), Blocks.COBBLESTONE.getDefaultState());
        world.setBlockState(new BlockPos(i + 6, j + 12, k + 9), Blocks.MOSSY_COBBLESTONE.getDefaultState());
        world.setBlockState(new BlockPos(i + 6, j + 12, k + 10), Blocks.COBBLESTONE.getDefaultState());
        world.setBlockState(new BlockPos(i + 6, j + 12, k + 11), Blocks.COBBLESTONE.getDefaultState());
        world.setBlockState(new BlockPos(i + 6, j + 12, k + 12), Blocks.COBBLESTONE.getDefaultState());
        world.setBlockState(new BlockPos(i + 6, j + 12, k + 13), Blocks.COBBLESTONE.getDefaultState());
        world.setBlockState(new BlockPos(i + 6, j + 12, k + 14), Blocks.COBBLESTONE.getDefaultState());
        world.setBlockState(new BlockPos(i + 6, j + 12, k + 15), Blocks.GRASS.getDefaultState());
        world.setBlockState(new BlockPos(i + 6, j + 13, k + 4), Blocks.GRASS.getDefaultState());
        world.setBlockState(new BlockPos(i + 6, j + 13, k + 5), Blocks.GRASS.getDefaultState());
        world.setBlockState(new BlockPos(i + 6, j + 13, k + 6), Blocks.GRASS.getDefaultState());
        world.setBlockState(new BlockPos(i + 6, j + 13, k + 7), Blocks.GRASS.getDefaultState());
        world.setBlockState(new BlockPos(i + 6, j + 13, k + 8), Blocks.GRASS.getDefaultState());
        world.setBlockState(new BlockPos(i + 6, j + 13, k + 9), Blocks.GRASS.getDefaultState());
        world.setBlockState(new BlockPos(i + 6, j + 13, k + 10), Blocks.GRASS.getDefaultState());
        world.setBlockState(new BlockPos(i + 6, j + 13, k + 11), Blocks.GRASS.getDefaultState());
        world.setBlockState(new BlockPos(i + 6, j + 13, k + 12), Blocks.GRASS.getDefaultState());
        world.setBlockState(new BlockPos(i + 6, j + 13, k + 13), Blocks.GRASS.getDefaultState());
        world.setBlockState(new BlockPos(i + 6, j + 13, k + 14), Blocks.GRASS.getDefaultState());
        world.setBlockState(new BlockPos(i + 7, j + 0, k + 6), Blocks.COBBLESTONE.getDefaultState());
        world.setBlockState(new BlockPos(i + 7, j + 0, k + 7), Blocks.MOSSY_COBBLESTONE.getDefaultState());
        world.setBlockState(new BlockPos(i + 7, j + 0, k + 8), Blocks.COBBLESTONE.getDefaultState());
        world.setBlockState(new BlockPos(i + 7, j + 0, k + 9), Blocks.COBBLESTONE.getDefaultState());
        world.setBlockState(new BlockPos(i + 7, j + 0, k + 10), Blocks.MOSSY_COBBLESTONE.getDefaultState());
        world.setBlockState(new BlockPos(i + 7, j + 0, k + 11), Blocks.MOSSY_COBBLESTONE.getDefaultState());
        world.setBlockState(new BlockPos(i + 7, j + 0, k + 12), Blocks.COBBLESTONE.getDefaultState());
        world.setBlockState(new BlockPos(i + 7, j + 1, k + 6), Blocks.MOSSY_COBBLESTONE.getDefaultState());
        world.setBlockState(new BlockPos(i + 7, j + 1, k + 12), Blocks.COBBLESTONE.getDefaultState());
        world.setBlockState(new BlockPos(i + 7, j + 2, k + 6), Blocks.COBBLESTONE.getDefaultState());
        world.setBlockState(new BlockPos(i + 7, j + 2, k + 12), Blocks.COBBLESTONE.getDefaultState());
        world.setBlockState(new BlockPos(i + 7, j + 3, k + 6), Blocks.COBBLESTONE.getDefaultState());
        world.setBlockState(new BlockPos(i + 7, j + 3, k + 12), Blocks.COBBLESTONE.getDefaultState());
        world.setBlockState(new BlockPos(i + 7, j + 4, k + 3), Blocks.COBBLESTONE.getDefaultState());
        world.setBlockState(new BlockPos(i + 7, j + 4, k + 4), Blocks.COBBLESTONE.getDefaultState());
        world.setBlockState(new BlockPos(i + 7, j + 4, k + 5), Blocks.COBBLESTONE.getDefaultState());
        world.setBlockState(new BlockPos(i + 7, j + 4, k + 6), Blocks.STONE_STAIRS.getDefaultState());
        world.setBlockState(new BlockPos(i + 7, j + 4, k + 12), Blocks.STONE_STAIRS.getStateFromMeta(2));
        world.setBlockState(new BlockPos(i + 7, j + 4, k + 13), Blocks.COBBLESTONE.getDefaultState());
        world.setBlockState(new BlockPos(i + 7, j + 4, k + 14), Blocks.COBBLESTONE.getDefaultState());
        world.setBlockState(new BlockPos(i + 7, j + 4, k + 15), Blocks.COBBLESTONE.getDefaultState());
        world.setBlockState(new BlockPos(i + 7, j + 5, k + 3), Blocks.COBBLESTONE.getDefaultState());
        world.setBlockState(new BlockPos(i + 7, j + 5, k + 15), Blocks.COBBLESTONE.getDefaultState());
        world.setBlockState(new BlockPos(i + 7, j + 6, k + 3), Blocks.COBBLESTONE.getDefaultState());
        world.setBlockState(new BlockPos(i + 7, j + 6, k + 15), Blocks.MOSSY_COBBLESTONE.getDefaultState());
        world.setBlockState(new BlockPos(i + 7, j + 7, k + 3), Blocks.COBBLESTONE.getDefaultState());
        world.setBlockState(new BlockPos(i + 7, j + 7, k + 15), Blocks.COBBLESTONE.getDefaultState());
        world.setBlockState(new BlockPos(i + 7, j + 8, k + 0), Blocks.DIRT.getDefaultState());
        world.setBlockState(new BlockPos(i + 7, j + 8, k + 1), Blocks.DIRT.getDefaultState());
        world.setBlockState(new BlockPos(i + 7, j + 8, k + 2), Blocks.DIRT.getDefaultState());
        world.setBlockState(new BlockPos(i + 7, j + 8, k + 3), Blocks.COBBLESTONE.getDefaultState());
        world.setBlockState(new BlockPos(i + 7, j + 8, k + 4), Blocks.COBBLESTONE.getDefaultState());
        world.setBlockState(new BlockPos(i + 7, j + 8, k + 5), Blocks.COBBLESTONE.getDefaultState());
        world.setBlockState(new BlockPos(i + 7, j + 8, k + 6), Blocks.STONE_STAIRS.getStateFromMeta(7));
        world.setBlockState(new BlockPos(i + 7, j + 8, k + 12), Blocks.STONE_STAIRS.getStateFromMeta(6));
        world.setBlockState(new BlockPos(i + 7, j + 8, k + 13), Blocks.COBBLESTONE.getDefaultState());
        world.setBlockState(new BlockPos(i + 7, j + 8, k + 14), Blocks.MOSSY_COBBLESTONE.getDefaultState());
        world.setBlockState(new BlockPos(i + 7, j + 8, k + 15), Blocks.COBBLESTONE.getDefaultState());
        world.setBlockState(new BlockPos(i + 7, j + 8, k + 16), Blocks.DIRT.getDefaultState());
        world.setBlockState(new BlockPos(i + 7, j + 8, k + 17), Blocks.DIRT.getDefaultState());
        world.setBlockState(new BlockPos(i + 7, j + 8, k + 18), Blocks.DIRT.getDefaultState());
        world.setBlockState(new BlockPos(i + 7, j + 9, k + 0), Blocks.GRASS.getDefaultState());
        world.setBlockState(new BlockPos(i + 7, j + 9, k + 1), Blocks.DIRT.getDefaultState());
        world.setBlockState(new BlockPos(i + 7, j + 9, k + 2), Blocks.DIRT.getDefaultState());
        world.setBlockState(new BlockPos(i + 7, j + 9, k + 3), Blocks.COBBLESTONE.getDefaultState());
        world.setBlockState(new BlockPos(i + 7, j + 9, k + 15), Blocks.COBBLESTONE.getDefaultState());
        world.setBlockState(new BlockPos(i + 7, j + 9, k + 16), Blocks.DIRT.getDefaultState());
        world.setBlockState(new BlockPos(i + 7, j + 9, k + 17), Blocks.DIRT.getDefaultState());
        world.setBlockState(new BlockPos(i + 7, j + 9, k + 18), Blocks.GRASS.getDefaultState());
        world.setBlockState(new BlockPos(i + 7, j + 10, k + 1), Blocks.DIRT.getDefaultState());
        world.setBlockState(new BlockPos(i + 7, j + 10, k + 2), Blocks.DIRT.getDefaultState());
        world.setBlockState(new BlockPos(i + 7, j + 10, k + 3), Blocks.COBBLESTONE.getDefaultState());
        world.setBlockState(new BlockPos(i + 7, j + 10, k + 15), Blocks.COBBLESTONE.getDefaultState());
        world.setBlockState(new BlockPos(i + 7, j + 10, k + 16), Blocks.DIRT.getDefaultState());
        world.setBlockState(new BlockPos(i + 7, j + 10, k + 17), Blocks.DIRT.getDefaultState());
        world.setBlockState(new BlockPos(i + 7, j + 11, k + 1), Blocks.GRASS.getDefaultState());
        world.setBlockState(new BlockPos(i + 7, j + 11, k + 2), Blocks.GRASS.getDefaultState());
        world.setBlockState(new BlockPos(i + 7, j + 11, k + 3), Blocks.MOSSY_COBBLESTONE.getDefaultState());
        world.setBlockState(new BlockPos(i + 7, j + 11, k + 6), Blocks.STONE_STAIRS.getStateFromMeta(5));
        world.setBlockState(new BlockPos(i + 7, j + 11, k + 12), Blocks.STONE_STAIRS.getStateFromMeta(5));
        world.setBlockState(new BlockPos(i + 7, j + 11, k + 15), Blocks.COBBLESTONE.getDefaultState());
        world.setBlockState(new BlockPos(i + 7, j + 11, k + 16), Blocks.GRASS.getDefaultState());
        world.setBlockState(new BlockPos(i + 7, j + 11, k + 17), Blocks.GRASS.getDefaultState());
        world.setBlockState(new BlockPos(i + 7, j + 12, k + 3), Blocks.GRASS.getDefaultState());
        world.setBlockState(new BlockPos(i + 7, j + 12, k + 4), Blocks.COBBLESTONE.getDefaultState());
        world.setBlockState(new BlockPos(i + 7, j + 12, k + 5), Blocks.COBBLESTONE.getDefaultState());
        world.setBlockState(new BlockPos(i + 7, j + 12, k + 6), Blocks.COBBLESTONE.getDefaultState());
        world.setBlockState(new BlockPos(i + 7, j + 12, k + 7), Blocks.COBBLESTONE.getDefaultState());
        world.setBlockState(new BlockPos(i + 7, j + 12, k + 8), Blocks.COBBLESTONE.getDefaultState());
        world.setBlockState(new BlockPos(i + 7, j + 12, k + 9), Blocks.MOSSY_COBBLESTONE.getDefaultState());
        world.setBlockState(new BlockPos(i + 7, j + 12, k + 10), Blocks.COBBLESTONE.getDefaultState());
        world.setBlockState(new BlockPos(i + 7, j + 12, k + 11), Blocks.COBBLESTONE.getDefaultState());
        world.setBlockState(new BlockPos(i + 7, j + 12, k + 12), Blocks.COBBLESTONE.getDefaultState());
        world.setBlockState(new BlockPos(i + 7, j + 12, k + 13), Blocks.COBBLESTONE.getDefaultState());
        world.setBlockState(new BlockPos(i + 7, j + 12, k + 14), Blocks.COBBLESTONE.getDefaultState());
        world.setBlockState(new BlockPos(i + 7, j + 12, k + 15), Blocks.GRASS.getDefaultState());
        world.setBlockState(new BlockPos(i + 7, j + 13, k + 4), Blocks.GRASS.getDefaultState());
        world.setBlockState(new BlockPos(i + 7, j + 13, k + 5), Blocks.GRASS.getDefaultState());
        world.setBlockState(new BlockPos(i + 7, j + 13, k + 6), Blocks.GRASS.getDefaultState());
        world.setBlockState(new BlockPos(i + 7, j + 13, k + 7), Blocks.DIRT.getDefaultState());
        world.setBlockState(new BlockPos(i + 7, j + 13, k + 8), Blocks.DIRT.getDefaultState());
        world.setBlockState(new BlockPos(i + 7, j + 13, k + 9), Blocks.DIRT.getDefaultState());
        world.setBlockState(new BlockPos(i + 7, j + 13, k + 10), Blocks.GRASS.getDefaultState());
        world.setBlockState(new BlockPos(i + 7, j + 13, k + 11), Blocks.GRASS.getDefaultState());
        world.setBlockState(new BlockPos(i + 7, j + 13, k + 12), Blocks.GRASS.getDefaultState());
        world.setBlockState(new BlockPos(i + 7, j + 13, k + 13), Blocks.GRASS.getDefaultState());
        world.setBlockState(new BlockPos(i + 7, j + 13, k + 14), Blocks.GRASS.getDefaultState());
        world.setBlockState(new BlockPos(i + 7, j + 14, k + 7), Blocks.GRASS.getDefaultState());
        world.setBlockState(new BlockPos(i + 7, j + 14, k + 8), Blocks.GRASS.getDefaultState());
        world.setBlockState(new BlockPos(i + 7, j + 14, k + 9), Blocks.GRASS.getDefaultState());
        world.setBlockState(new BlockPos(i + 8, j + 0, k + 6), Blocks.COBBLESTONE.getDefaultState());
        world.setBlockState(new BlockPos(i + 8, j + 0, k + 7), Blocks.COBBLESTONE.getDefaultState());
        world.setBlockState(new BlockPos(i + 8, j + 0, k + 8), Blocks.COBBLESTONE.getDefaultState());
        world.setBlockState(new BlockPos(i + 8, j + 0, k + 9), Blocks.COBBLESTONE.getDefaultState());
        world.setBlockState(new BlockPos(i + 8, j + 0, k + 10), Blocks.COBBLESTONE.getDefaultState());
        world.setBlockState(new BlockPos(i + 8, j + 0, k + 11), Blocks.COBBLESTONE.getDefaultState());
        world.setBlockState(new BlockPos(i + 8, j + 0, k + 12), Blocks.COBBLESTONE.getDefaultState());
        world.setBlockState(new BlockPos(i + 8, j + 1, k + 6), Blocks.COBBLESTONE.getDefaultState());
        world.setBlockState(new BlockPos(i + 8, j + 1, k + 12), Blocks.MOSSY_COBBLESTONE.getDefaultState());
        world.setBlockState(new BlockPos(i + 8, j + 2, k + 6), Blocks.COBBLESTONE.getDefaultState());
        world.setBlockState(new BlockPos(i + 8, j + 2, k + 12), Blocks.COBBLESTONE.getDefaultState());
        world.setBlockState(new BlockPos(i + 8, j + 3, k + 6), Blocks.COBBLESTONE.getDefaultState());
        world.setBlockState(new BlockPos(i + 8, j + 3, k + 12), Blocks.COBBLESTONE.getDefaultState());
        world.setBlockState(new BlockPos(i + 8, j + 4, k + 3), Blocks.COBBLESTONE.getDefaultState());
        world.setBlockState(new BlockPos(i + 8, j + 4, k + 4), Blocks.COBBLESTONE.getDefaultState());
        world.setBlockState(new BlockPos(i + 8, j + 4, k + 5), Blocks.MOSSY_COBBLESTONE.getDefaultState());
        world.setBlockState(new BlockPos(i + 8, j + 4, k + 6), Blocks.STONE_STAIRS.getDefaultState());
        world.setBlockState(new BlockPos(i + 8, j + 4, k + 12), Blocks.STONE_STAIRS.getStateFromMeta(2));
        world.setBlockState(new BlockPos(i + 8, j + 4, k + 13), Blocks.COBBLESTONE.getDefaultState());
        world.setBlockState(new BlockPos(i + 8, j + 4, k + 14), Blocks.COBBLESTONE.getDefaultState());
        world.setBlockState(new BlockPos(i + 8, j + 4, k + 15), Blocks.COBBLESTONE.getDefaultState());
        world.setBlockState(new BlockPos(i + 8, j + 5, k + 3), Blocks.COBBLESTONE.getDefaultState());
        world.setBlockState(new BlockPos(i + 8, j + 5, k + 15), Blocks.COBBLESTONE.getDefaultState());
        world.setBlockState(new BlockPos(i + 8, j + 6, k + 3), Blocks.MOSSY_COBBLESTONE.getDefaultState());
        world.setBlockState(new BlockPos(i + 8, j + 6, k + 15), Blocks.COBBLESTONE.getDefaultState());
        world.setBlockState(new BlockPos(i + 8, j + 7, k + 3), Blocks.COBBLESTONE.getDefaultState());
        world.setBlockState(new BlockPos(i + 8, j + 7, k + 15), Blocks.COBBLESTONE.getDefaultState());
        world.setBlockState(new BlockPos(i + 8, j + 8, k + 0), Blocks.DIRT.getDefaultState());
        world.setBlockState(new BlockPos(i + 8, j + 8, k + 1), Blocks.DIRT.getDefaultState());
        world.setBlockState(new BlockPos(i + 8, j + 8, k + 2), Blocks.DIRT.getDefaultState());
        world.setBlockState(new BlockPos(i + 8, j + 8, k + 3), Blocks.COBBLESTONE.getDefaultState());
        world.setBlockState(new BlockPos(i + 8, j + 8, k + 4), Blocks.COBBLESTONE.getDefaultState());
        world.setBlockState(new BlockPos(i + 8, j + 8, k + 5), Blocks.MOSSY_COBBLESTONE.getDefaultState());
        world.setBlockState(new BlockPos(i + 8, j + 8, k + 6), Blocks.STONE_STAIRS.getStateFromMeta(7));
        world.setBlockState(new BlockPos(i + 8, j + 8, k + 12), Blocks.STONE_STAIRS.getStateFromMeta(6));
        world.setBlockState(new BlockPos(i + 8, j + 8, k + 13), Blocks.COBBLESTONE.getDefaultState());
        world.setBlockState(new BlockPos(i + 8, j + 8, k + 14), Blocks.COBBLESTONE.getDefaultState());
        world.setBlockState(new BlockPos(i + 8, j + 8, k + 15), Blocks.COBBLESTONE.getDefaultState());
        world.setBlockState(new BlockPos(i + 8, j + 8, k + 16), Blocks.DIRT.getDefaultState());
        world.setBlockState(new BlockPos(i + 8, j + 8, k + 17), Blocks.DIRT.getDefaultState());
        world.setBlockState(new BlockPos(i + 8, j + 8, k + 18), Blocks.DIRT.getDefaultState());
        world.setBlockState(new BlockPos(i + 8, j + 9, k + 0), Blocks.GRASS.getDefaultState());
        world.setBlockState(new BlockPos(i + 8, j + 9, k + 1), Blocks.DIRT.getDefaultState());
        world.setBlockState(new BlockPos(i + 8, j + 9, k + 2), Blocks.DIRT.getDefaultState());
        world.setBlockState(new BlockPos(i + 8, j + 9, k + 3), Blocks.COBBLESTONE.getDefaultState());
        world.setBlockState(new BlockPos(i + 8, j + 9, k + 15), Blocks.COBBLESTONE.getDefaultState());
        world.setBlockState(new BlockPos(i + 8, j + 9, k + 16), Blocks.DIRT.getDefaultState());
        world.setBlockState(new BlockPos(i + 8, j + 9, k + 17), Blocks.DIRT.getDefaultState());
        world.setBlockState(new BlockPos(i + 8, j + 9, k + 18), Blocks.GRASS.getDefaultState());
        world.setBlockState(new BlockPos(i + 8, j + 10, k + 1), Blocks.GRASS.getDefaultState());
        world.setBlockState(new BlockPos(i + 8, j + 10, k + 2), Blocks.DIRT.getDefaultState());
        world.setBlockState(new BlockPos(i + 8, j + 10, k + 3), Blocks.MOSSY_COBBLESTONE.getDefaultState());
        world.setBlockState(new BlockPos(i + 8, j + 10, k + 15), Blocks.MOSSY_COBBLESTONE.getDefaultState());
        world.setBlockState(new BlockPos(i + 8, j + 10, k + 16), Blocks.DIRT.getDefaultState());
        world.setBlockState(new BlockPos(i + 8, j + 10, k + 17), Blocks.DIRT.getDefaultState());
        world.setBlockState(new BlockPos(i + 8, j + 11, k + 2), Blocks.GRASS.getDefaultState());
        world.setBlockState(new BlockPos(i + 8, j + 11, k + 3), Blocks.COBBLESTONE.getDefaultState());
        world.setBlockState(new BlockPos(i + 8, j + 11, k + 15), Blocks.COBBLESTONE.getDefaultState());
        world.setBlockState(new BlockPos(i + 8, j + 11, k + 16), Blocks.GRASS.getDefaultState());
        world.setBlockState(new BlockPos(i + 8, j + 11, k + 17), Blocks.GRASS.getDefaultState());
        world.setBlockState(new BlockPos(i + 8, j + 12, k + 3), Blocks.GRASS.getDefaultState());
        world.setBlockState(new BlockPos(i + 8, j + 12, k + 4), Blocks.COBBLESTONE.getDefaultState());
        world.setBlockState(new BlockPos(i + 8, j + 12, k + 5), Blocks.COBBLESTONE.getDefaultState());
        world.setBlockState(new BlockPos(i + 8, j + 12, k + 6), Blocks.COBBLESTONE.getDefaultState());
        world.setBlockState(new BlockPos(i + 8, j + 12, k + 7), Blocks.MOSSY_COBBLESTONE.getDefaultState());
        world.setBlockState(new BlockPos(i + 8, j + 12, k + 8), Blocks.COBBLESTONE.getDefaultState());
        world.setBlockState(new BlockPos(i + 8, j + 12, k + 9), Blocks.COBBLESTONE.getDefaultState());
        world.setBlockState(new BlockPos(i + 8, j + 12, k + 10), Blocks.COBBLESTONE.getDefaultState());
        world.setBlockState(new BlockPos(i + 8, j + 12, k + 11), Blocks.COBBLESTONE.getDefaultState());
        world.setBlockState(new BlockPos(i + 8, j + 12, k + 12), Blocks.COBBLESTONE.getDefaultState());
        world.setBlockState(new BlockPos(i + 8, j + 12, k + 13), Blocks.COBBLESTONE.getDefaultState());
        world.setBlockState(new BlockPos(i + 8, j + 12, k + 14), Blocks.COBBLESTONE.getDefaultState());
        world.setBlockState(new BlockPos(i + 8, j + 12, k + 15), Blocks.GRASS.getDefaultState());
        world.setBlockState(new BlockPos(i + 8, j + 13, k + 4), Blocks.GRASS.getDefaultState());
        world.setBlockState(new BlockPos(i + 8, j + 13, k + 5), Blocks.GRASS.getDefaultState());
        world.setBlockState(new BlockPos(i + 8, j + 13, k + 6), Blocks.DIRT.getDefaultState());
        world.setBlockState(new BlockPos(i + 8, j + 13, k + 7), Blocks.DIRT.getDefaultState());
        world.setBlockState(new BlockPos(i + 8, j + 13, k + 8), Blocks.DIRT.getDefaultState());
        world.setBlockState(new BlockPos(i + 8, j + 13, k + 9), Blocks.DIRT.getDefaultState());
        world.setBlockState(new BlockPos(i + 8, j + 13, k + 10), Blocks.DIRT.getDefaultState());
        world.setBlockState(new BlockPos(i + 8, j + 13, k + 11), Blocks.GRASS.getDefaultState());
        world.setBlockState(new BlockPos(i + 8, j + 13, k + 12), Blocks.GRASS.getDefaultState());
        world.setBlockState(new BlockPos(i + 8, j + 13, k + 13), Blocks.GRASS.getDefaultState());
        world.setBlockState(new BlockPos(i + 8, j + 13, k + 14), Blocks.GRASS.getDefaultState());
        world.setBlockState(new BlockPos(i + 8, j + 14, k + 6), Blocks.GRASS.getDefaultState());
        world.setBlockState(new BlockPos(i + 8, j + 14, k + 7), Blocks.GRASS.getDefaultState());
        world.setBlockState(new BlockPos(i + 8, j + 14, k + 8), Blocks.GRASS.getDefaultState());
        world.setBlockState(new BlockPos(i + 8, j + 14, k + 9), Blocks.GRASS.getDefaultState());
        world.setBlockState(new BlockPos(i + 8, j + 14, k + 10), Blocks.GRASS.getDefaultState());
        world.setBlockState(new BlockPos(i + 9, j + 0, k + 6), Blocks.COBBLESTONE.getDefaultState());
        world.setBlockState(new BlockPos(i + 9, j + 0, k + 7), Blocks.COBBLESTONE.getDefaultState());
        world.setBlockState(new BlockPos(i + 9, j + 0, k + 8), Blocks.MOSSY_COBBLESTONE.getDefaultState());
        world.setBlockState(new BlockPos(i + 9, j + 0, k + 9), Blocks.COBBLESTONE.getDefaultState());
        world.setBlockState(new BlockPos(i + 9, j + 0, k + 10), Blocks.MOSSY_COBBLESTONE.getDefaultState());
        world.setBlockState(new BlockPos(i + 9, j + 0, k + 11), Blocks.MOSSY_COBBLESTONE.getDefaultState());
        world.setBlockState(new BlockPos(i + 9, j + 0, k + 12), Blocks.COBBLESTONE.getDefaultState());
        world.setBlockState(new BlockPos(i + 9, j + 1, k + 6), Blocks.MOSSY_COBBLESTONE.getDefaultState());
        world.setBlockState(new BlockPos(i + 9, j + 1, k + 12), Blocks.MOSSY_COBBLESTONE.getDefaultState());
        world.setBlockState(new BlockPos(i + 9, j + 2, k + 6), Blocks.COBBLESTONE.getDefaultState());
        world.setBlockState(new BlockPos(i + 9, j + 2, k + 12), Blocks.COBBLESTONE.getDefaultState());
        world.setBlockState(new BlockPos(i + 9, j + 3, k + 6), Blocks.COBBLESTONE.getDefaultState());
        world.setBlockState(new BlockPos(i + 9, j + 3, k + 12), Blocks.MOSSY_COBBLESTONE.getDefaultState());
        world.setBlockState(new BlockPos(i + 9, j + 4, k + 3), Blocks.COBBLESTONE.getDefaultState());
        world.setBlockState(new BlockPos(i + 9, j + 4, k + 4), Blocks.COBBLESTONE.getDefaultState());
        world.setBlockState(new BlockPos(i + 9, j + 4, k + 5), Blocks.COBBLESTONE.getDefaultState());
        world.setBlockState(new BlockPos(i + 9, j + 4, k + 6), Blocks.STONE_STAIRS.getDefaultState());
        world.setBlockState(new BlockPos(i + 9, j + 4, k + 12), Blocks.STONE_STAIRS.getStateFromMeta(2));
        world.setBlockState(new BlockPos(i + 9, j + 4, k + 13), Blocks.COBBLESTONE.getDefaultState());
        world.setBlockState(new BlockPos(i + 9, j + 4, k + 14), Blocks.COBBLESTONE.getDefaultState());
        world.setBlockState(new BlockPos(i + 9, j + 4, k + 15), Blocks.COBBLESTONE.getDefaultState());
        world.setBlockState(new BlockPos(i + 9, j + 5, k + 3), Blocks.COBBLESTONE.getDefaultState());
        world.setBlockState(new BlockPos(i + 9, j + 5, k + 15), Blocks.COBBLESTONE.getDefaultState());
        world.setBlockState(new BlockPos(i + 9, j + 6, k + 3), Blocks.COBBLESTONE.getDefaultState());
        world.setBlockState(new BlockPos(i + 9, j + 6, k + 15), Blocks.COBBLESTONE.getDefaultState());
        world.setBlockState(new BlockPos(i + 9, j + 7, k + 3), Blocks.COBBLESTONE.getDefaultState());
        world.setBlockState(new BlockPos(i + 9, j + 7, k + 15), Blocks.COBBLESTONE.getDefaultState());
        world.setBlockState(new BlockPos(i + 9, j + 8, k + 0), Blocks.DIRT.getDefaultState());
        world.setBlockState(new BlockPos(i + 9, j + 8, k + 1), Blocks.DIRT.getDefaultState());
        world.setBlockState(new BlockPos(i + 9, j + 8, k + 2), Blocks.DIRT.getDefaultState());
        world.setBlockState(new BlockPos(i + 9, j + 8, k + 3), Blocks.COBBLESTONE.getDefaultState());
        world.setBlockState(new BlockPos(i + 9, j + 8, k + 4), Blocks.COBBLESTONE.getDefaultState());
        world.setBlockState(new BlockPos(i + 9, j + 8, k + 5), Blocks.COBBLESTONE.getDefaultState());
        world.setBlockState(new BlockPos(i + 9, j + 8, k + 6), Blocks.STONE_STAIRS.getStateFromMeta(7));
        world.setBlockState(new BlockPos(i + 9, j + 8, k + 12), Blocks.STONE_STAIRS.getStateFromMeta(6));
        world.setBlockState(new BlockPos(i + 9, j + 8, k + 13), Blocks.MOSSY_COBBLESTONE.getDefaultState());
        world.setBlockState(new BlockPos(i + 9, j + 8, k + 14), Blocks.COBBLESTONE.getDefaultState());
        world.setBlockState(new BlockPos(i + 9, j + 8, k + 15), Blocks.COBBLESTONE.getDefaultState());
        world.setBlockState(new BlockPos(i + 9, j + 8, k + 16), Blocks.DIRT.getDefaultState());
        world.setBlockState(new BlockPos(i + 9, j + 8, k + 17), Blocks.DIRT.getDefaultState());
        world.setBlockState(new BlockPos(i + 9, j + 8, k + 18), Blocks.DIRT.getDefaultState());
        world.setBlockState(new BlockPos(i + 9, j + 9, k + 0), Blocks.DIRT.getDefaultState());
        world.setBlockState(new BlockPos(i + 9, j + 9, k + 1), Blocks.DIRT.getDefaultState());
        world.setBlockState(new BlockPos(i + 9, j + 9, k + 2), Blocks.DIRT.getDefaultState());
        world.setBlockState(new BlockPos(i + 9, j + 9, k + 3), Blocks.COBBLESTONE.getDefaultState());
        world.setBlockState(new BlockPos(i + 9, j + 9, k + 15), Blocks.MOSSY_COBBLESTONE.getDefaultState());
        world.setBlockState(new BlockPos(i + 9, j + 9, k + 16), Blocks.DIRT.getDefaultState());
        world.setBlockState(new BlockPos(i + 9, j + 9, k + 17), Blocks.DIRT.getDefaultState());
        world.setBlockState(new BlockPos(i + 9, j + 9, k + 18), Blocks.GRASS.getDefaultState());
        world.setBlockState(new BlockPos(i + 9, j + 10, k + 0), Blocks.GRASS.getDefaultState());
        world.setBlockState(new BlockPos(i + 9, j + 10, k + 1), Blocks.DIRT.getDefaultState());
        world.setBlockState(new BlockPos(i + 9, j + 10, k + 2), Blocks.DIRT.getDefaultState());
        world.setBlockState(new BlockPos(i + 9, j + 10, k + 3), Blocks.MOSSY_COBBLESTONE.getDefaultState());
        world.setBlockState(new BlockPos(i + 9, j + 10, k + 15), Blocks.MOSSY_COBBLESTONE.getDefaultState());
        world.setBlockState(new BlockPos(i + 9, j + 10, k + 16), Blocks.DIRT.getDefaultState());
        world.setBlockState(new BlockPos(i + 9, j + 10, k + 17), Blocks.GRASS.getDefaultState());
        world.setBlockState(new BlockPos(i + 9, j + 11, k + 1), Blocks.GRASS.getDefaultState());
        world.setBlockState(new BlockPos(i + 9, j + 11, k + 2), Blocks.DIRT.getDefaultState());
        world.setBlockState(new BlockPos(i + 9, j + 11, k + 3), Blocks.COBBLESTONE.getDefaultState());
        world.setBlockState(new BlockPos(i + 9, j + 11, k + 15), Blocks.COBBLESTONE.getDefaultState());
        world.setBlockState(new BlockPos(i + 9, j + 11, k + 16), Blocks.DIRT.getDefaultState());
        world.setBlockState(new BlockPos(i + 9, j + 12, k + 2), Blocks.GRASS.getDefaultState());
        world.setBlockState(new BlockPos(i + 9, j + 12, k + 3), Blocks.GRASS.getDefaultState());
        world.setBlockState(new BlockPos(i + 9, j + 12, k + 4), Blocks.COBBLESTONE.getDefaultState());
        world.setBlockState(new BlockPos(i + 9, j + 12, k + 5), Blocks.COBBLESTONE.getDefaultState());
        world.setBlockState(new BlockPos(i + 9, j + 12, k + 6), Blocks.COBBLESTONE.getDefaultState());
        world.setBlockState(new BlockPos(i + 9, j + 12, k + 7), Blocks.MOSSY_COBBLESTONE.getDefaultState());
        world.setBlockState(new BlockPos(i + 9, j + 12, k + 8), Blocks.COBBLESTONE.getDefaultState());
        world.setBlockState(new BlockPos(i + 9, j + 12, k + 9), Blocks.COBBLESTONE.getDefaultState());
        world.setBlockState(new BlockPos(i + 9, j + 12, k + 10), Blocks.COBBLESTONE.getDefaultState());
        world.setBlockState(new BlockPos(i + 9, j + 12, k + 11), Blocks.COBBLESTONE.getDefaultState());
        world.setBlockState(new BlockPos(i + 9, j + 12, k + 12), Blocks.COBBLESTONE.getDefaultState());
        world.setBlockState(new BlockPos(i + 9, j + 12, k + 13), Blocks.COBBLESTONE.getDefaultState());
        world.setBlockState(new BlockPos(i + 9, j + 12, k + 14), Blocks.COBBLESTONE.getDefaultState());
        world.setBlockState(new BlockPos(i + 9, j + 12, k + 15), Blocks.GRASS.getDefaultState());
        world.setBlockState(new BlockPos(i + 9, j + 12, k + 16), Blocks.GRASS.getDefaultState());
        world.setBlockState(new BlockPos(i + 9, j + 13, k + 4), Blocks.GRASS.getDefaultState());
        world.setBlockState(new BlockPos(i + 9, j + 13, k + 5), Blocks.GRASS.getDefaultState());
        world.setBlockState(new BlockPos(i + 9, j + 13, k + 6), Blocks.DIRT.getDefaultState());
        world.setBlockState(new BlockPos(i + 9, j + 13, k + 7), Blocks.DIRT.getDefaultState());
        world.setBlockState(new BlockPos(i + 9, j + 13, k + 8), Blocks.DIRT.getDefaultState());
        world.setBlockState(new BlockPos(i + 9, j + 13, k + 9), Blocks.DIRT.getDefaultState());
        world.setBlockState(new BlockPos(i + 9, j + 13, k + 10), Blocks.DIRT.getDefaultState());
        world.setBlockState(new BlockPos(i + 9, j + 13, k + 11), Blocks.DIRT.getDefaultState());
        world.setBlockState(new BlockPos(i + 9, j + 13, k + 12), Blocks.GRASS.getDefaultState());
        world.setBlockState(new BlockPos(i + 9, j + 13, k + 13), Blocks.GRASS.getDefaultState());
        world.setBlockState(new BlockPos(i + 9, j + 13, k + 14), Blocks.GRASS.getDefaultState());
        world.setBlockState(new BlockPos(i + 9, j + 14, k + 6), Blocks.GRASS.getDefaultState());
        world.setBlockState(new BlockPos(i + 9, j + 14, k + 7), Blocks.GRASS.getDefaultState());
        world.setBlockState(new BlockPos(i + 9, j + 14, k + 8), Blocks.GRASS.getDefaultState());
        world.setBlockState(new BlockPos(i + 9, j + 14, k + 9), Blocks.GRASS.getDefaultState());
        world.setBlockState(new BlockPos(i + 9, j + 14, k + 10), Blocks.GRASS.getDefaultState());
        world.setBlockState(new BlockPos(i + 9, j + 14, k + 11), Blocks.GRASS.getDefaultState());
        world.setBlockState(new BlockPos(i + 10, j + 0, k + 6), Blocks.COBBLESTONE.getDefaultState());
        world.setBlockState(new BlockPos(i + 10, j + 0, k + 7), Blocks.MOSSY_COBBLESTONE.getDefaultState());
        world.setBlockState(new BlockPos(i + 10, j + 0, k + 8), Blocks.MOSSY_COBBLESTONE.getDefaultState());
        world.setBlockState(new BlockPos(i + 10, j + 0, k + 9), Blocks.COBBLESTONE.getDefaultState());
        world.setBlockState(new BlockPos(i + 10, j + 0, k + 10), Blocks.COBBLESTONE.getDefaultState());
        world.setBlockState(new BlockPos(i + 10, j + 0, k + 11), Blocks.MOSSY_COBBLESTONE.getDefaultState());
        world.setBlockState(new BlockPos(i + 10, j + 0, k + 12), Blocks.COBBLESTONE.getDefaultState());
        world.setBlockState(new BlockPos(i + 10, j + 1, k + 6), Blocks.COBBLESTONE.getDefaultState());
        world.setBlockState(new BlockPos(i + 10, j + 1, k + 12), Blocks.COBBLESTONE.getDefaultState());
        world.setBlockState(new BlockPos(i + 10, j + 2, k + 6), Blocks.COBBLESTONE.getDefaultState());
        world.setBlockState(new BlockPos(i + 10, j + 2, k + 12), Blocks.COBBLESTONE.getDefaultState());
        world.setBlockState(new BlockPos(i + 10, j + 3, k + 6), Blocks.COBBLESTONE.getDefaultState());
        world.setBlockState(new BlockPos(i + 10, j + 3, k + 12), Blocks.COBBLESTONE.getDefaultState());
        world.setBlockState(new BlockPos(i + 10, j + 4, k + 3), Blocks.COBBLESTONE.getDefaultState());
        world.setBlockState(new BlockPos(i + 10, j + 4, k + 4), Blocks.MOSSY_COBBLESTONE.getDefaultState());
        world.setBlockState(new BlockPos(i + 10, j + 4, k + 5), Blocks.COBBLESTONE.getDefaultState());
        world.setBlockState(new BlockPos(i + 10, j + 4, k + 6), Blocks.STONE_STAIRS.getDefaultState());
        world.setBlockState(new BlockPos(i + 10, j + 4, k + 12), Blocks.STONE_STAIRS.getStateFromMeta(2));
        world.setBlockState(new BlockPos(i + 10, j + 4, k + 13), Blocks.COBBLESTONE.getDefaultState());
        world.setBlockState(new BlockPos(i + 10, j + 4, k + 14), Blocks.COBBLESTONE.getDefaultState());
        world.setBlockState(new BlockPos(i + 10, j + 4, k + 15), Blocks.COBBLESTONE.getDefaultState());
        world.setBlockState(new BlockPos(i + 10, j + 5, k + 3), Blocks.COBBLESTONE.getDefaultState());
        world.setBlockState(new BlockPos(i + 10, j + 5, k + 15), Blocks.COBBLESTONE.getDefaultState());
        world.setBlockState(new BlockPos(i + 10, j + 6, k + 3), Blocks.COBBLESTONE.getDefaultState());
        world.setBlockState(new BlockPos(i + 10, j + 6, k + 15), Blocks.MOSSY_COBBLESTONE.getDefaultState());
        world.setBlockState(new BlockPos(i + 10, j + 7, k + 3), Blocks.COBBLESTONE.getDefaultState());
        world.setBlockState(new BlockPos(i + 10, j + 7, k + 15), Blocks.COBBLESTONE.getDefaultState());
        world.setBlockState(new BlockPos(i + 10, j + 8, k + 0), Blocks.DIRT.getDefaultState());
        world.setBlockState(new BlockPos(i + 10, j + 8, k + 1), Blocks.DIRT.getDefaultState());
        world.setBlockState(new BlockPos(i + 10, j + 8, k + 2), Blocks.DIRT.getDefaultState());
        world.setBlockState(new BlockPos(i + 10, j + 8, k + 3), Blocks.COBBLESTONE.getDefaultState());
        world.setBlockState(new BlockPos(i + 10, j + 8, k + 4), Blocks.MOSSY_COBBLESTONE.getDefaultState());
        world.setBlockState(new BlockPos(i + 10, j + 8, k + 5), Blocks.COBBLESTONE.getDefaultState());
        world.setBlockState(new BlockPos(i + 10, j + 8, k + 6), Blocks.STONE_STAIRS.getStateFromMeta(7));
        world.setBlockState(new BlockPos(i + 10, j + 8, k + 12), Blocks.STONE_STAIRS.getStateFromMeta(6));
        world.setBlockState(new BlockPos(i + 10, j + 8, k + 13), Blocks.COBBLESTONE.getDefaultState());
        world.setBlockState(new BlockPos(i + 10, j + 8, k + 14), Blocks.COBBLESTONE.getDefaultState());
        world.setBlockState(new BlockPos(i + 10, j + 8, k + 15), Blocks.COBBLESTONE.getDefaultState());
        world.setBlockState(new BlockPos(i + 10, j + 8, k + 16), Blocks.DIRT.getDefaultState());
        world.setBlockState(new BlockPos(i + 10, j + 8, k + 17), Blocks.DIRT.getDefaultState());
        world.setBlockState(new BlockPos(i + 10, j + 8, k + 18), Blocks.DIRT.getDefaultState());
        world.setBlockState(new BlockPos(i + 10, j + 9, k + 0), Blocks.DIRT.getDefaultState());
        world.setBlockState(new BlockPos(i + 10, j + 9, k + 1), Blocks.DIRT.getDefaultState());
        world.setBlockState(new BlockPos(i + 10, j + 9, k + 2), Blocks.DIRT.getDefaultState());
        world.setBlockState(new BlockPos(i + 10, j + 9, k + 3), Blocks.COBBLESTONE.getDefaultState());
        world.setBlockState(new BlockPos(i + 10, j + 9, k + 15), Blocks.COBBLESTONE.getDefaultState());
        world.setBlockState(new BlockPos(i + 10, j + 9, k + 16), Blocks.DIRT.getDefaultState());
        world.setBlockState(new BlockPos(i + 10, j + 9, k + 17), Blocks.DIRT.getDefaultState());
        world.setBlockState(new BlockPos(i + 10, j + 9, k + 18), Blocks.GRASS.getDefaultState());
        world.setBlockState(new BlockPos(i + 10, j + 10, k + 0), Blocks.GRASS.getDefaultState());
        world.setBlockState(new BlockPos(i + 10, j + 10, k + 1), Blocks.DIRT.getDefaultState());
        world.setBlockState(new BlockPos(i + 10, j + 10, k + 2), Blocks.DIRT.getDefaultState());
        world.setBlockState(new BlockPos(i + 10, j + 10, k + 3), Blocks.COBBLESTONE.getDefaultState());
        world.setBlockState(new BlockPos(i + 10, j + 10, k + 15), Blocks.COBBLESTONE.getDefaultState());
        world.setBlockState(new BlockPos(i + 10, j + 10, k + 16), Blocks.DIRT.getDefaultState());
        world.setBlockState(new BlockPos(i + 10, j + 10, k + 17), Blocks.GRASS.getDefaultState());
        world.setBlockState(new BlockPos(i + 10, j + 11, k + 1), Blocks.GRASS.getDefaultState());
        world.setBlockState(new BlockPos(i + 10, j + 11, k + 2), Blocks.GRASS.getDefaultState());
        world.setBlockState(new BlockPos(i + 10, j + 11, k + 3), Blocks.COBBLESTONE.getDefaultState());
        world.setBlockState(new BlockPos(i + 10, j + 11, k + 6), Blocks.STONE_STAIRS.getStateFromMeta(4));
        world.setBlockState(new BlockPos(i + 10, j + 11, k + 12), Blocks.STONE_STAIRS.getStateFromMeta(4));
        world.setBlockState(new BlockPos(i + 10, j + 11, k + 15), Blocks.COBBLESTONE.getDefaultState());
        world.setBlockState(new BlockPos(i + 10, j + 11, k + 16), Blocks.DIRT.getDefaultState());
        world.setBlockState(new BlockPos(i + 10, j + 12, k + 3), Blocks.GRASS.getDefaultState());
        world.setBlockState(new BlockPos(i + 10, j + 12, k + 4), Blocks.COBBLESTONE.getDefaultState());
        world.setBlockState(new BlockPos(i + 10, j + 12, k + 5), Blocks.COBBLESTONE.getDefaultState());
        world.setBlockState(new BlockPos(i + 10, j + 12, k + 6), Blocks.COBBLESTONE.getDefaultState());
        world.setBlockState(new BlockPos(i + 10, j + 12, k + 7), Blocks.COBBLESTONE.getDefaultState());
        world.setBlockState(new BlockPos(i + 10, j + 12, k + 8), Blocks.COBBLESTONE.getDefaultState());
        world.setBlockState(new BlockPos(i + 10, j + 12, k + 9), Blocks.MOSSY_COBBLESTONE.getDefaultState());
        world.setBlockState(new BlockPos(i + 10, j + 12, k + 10), Blocks.COBBLESTONE.getDefaultState());
        world.setBlockState(new BlockPos(i + 10, j + 12, k + 11), Blocks.COBBLESTONE.getDefaultState());
        world.setBlockState(new BlockPos(i + 10, j + 12, k + 12), Blocks.MOSSY_COBBLESTONE.getDefaultState());
        world.setBlockState(new BlockPos(i + 10, j + 12, k + 13), Blocks.COBBLESTONE.getDefaultState());
        world.setBlockState(new BlockPos(i + 10, j + 12, k + 14), Blocks.COBBLESTONE.getDefaultState());
        world.setBlockState(new BlockPos(i + 10, j + 12, k + 15), Blocks.GRASS.getDefaultState());
        world.setBlockState(new BlockPos(i + 10, j + 12, k + 16), Blocks.GRASS.getDefaultState());
        world.setBlockState(new BlockPos(i + 10, j + 13, k + 4), Blocks.GRASS.getDefaultState());
        world.setBlockState(new BlockPos(i + 10, j + 13, k + 5), Blocks.DIRT.getDefaultState());
        world.setBlockState(new BlockPos(i + 10, j + 13, k + 6), Blocks.DIRT.getDefaultState());
        world.setBlockState(new BlockPos(i + 10, j + 13, k + 7), Blocks.GRASS.getDefaultState());
        world.setBlockState(new BlockPos(i + 10, j + 13, k + 8), Blocks.DIRT.getDefaultState());
        world.setBlockState(new BlockPos(i + 10, j + 13, k + 9), Blocks.DIRT.getDefaultState());
        world.setBlockState(new BlockPos(i + 10, j + 13, k + 10), Blocks.DIRT.getDefaultState());
        world.setBlockState(new BlockPos(i + 10, j + 13, k + 11), Blocks.DIRT.getDefaultState());
        world.setBlockState(new BlockPos(i + 10, j + 13, k + 12), Blocks.GRASS.getDefaultState());
        world.setBlockState(new BlockPos(i + 10, j + 13, k + 13), Blocks.GRASS.getDefaultState());
        world.setBlockState(new BlockPos(i + 10, j + 13, k + 14), Blocks.GRASS.getDefaultState());
        world.setBlockState(new BlockPos(i + 10, j + 14, k + 5), Blocks.GRASS.getDefaultState());
        world.setBlockState(new BlockPos(i + 10, j + 14, k + 6), Blocks.GRASS.getDefaultState());
        world.setBlockState(new BlockPos(i + 10, j + 14, k + 8), Blocks.GRASS.getDefaultState());
        world.setBlockState(new BlockPos(i + 10, j + 14, k + 9), Blocks.GRASS.getDefaultState());
        world.setBlockState(new BlockPos(i + 10, j + 14, k + 10), Blocks.GRASS.getDefaultState());
        world.setBlockState(new BlockPos(i + 10, j + 14, k + 11), Blocks.GRASS.getDefaultState());
        world.setBlockState(new BlockPos(i + 11, j + 0, k + 6), Blocks.COBBLESTONE.getDefaultState());
        world.setBlockState(new BlockPos(i + 11, j + 0, k + 7), Blocks.COBBLESTONE.getDefaultState());
        world.setBlockState(new BlockPos(i + 11, j + 0, k + 8), Blocks.COBBLESTONE.getDefaultState());
        world.setBlockState(new BlockPos(i + 11, j + 0, k + 9), Blocks.COBBLESTONE.getDefaultState());
        world.setBlockState(new BlockPos(i + 11, j + 0, k + 10), Blocks.MOSSY_COBBLESTONE.getDefaultState());
        world.setBlockState(new BlockPos(i + 11, j + 0, k + 11), Blocks.COBBLESTONE.getDefaultState());
        world.setBlockState(new BlockPos(i + 11, j + 0, k + 12), Blocks.COBBLESTONE.getDefaultState());
        world.setBlockState(new BlockPos(i + 11, j + 1, k + 6), Blocks.COBBLESTONE.getDefaultState());
        world.setBlockState(new BlockPos(i + 11, j + 1, k + 7), Blocks.COBBLESTONE.getDefaultState());
        world.setBlockState(new BlockPos(i + 11, j + 1, k + 8), Blocks.COBBLESTONE.getDefaultState());
        world.setBlockState(new BlockPos(i + 11, j + 1, k + 9), Blocks.COBBLESTONE.getDefaultState());
        world.setBlockState(new BlockPos(i + 11, j + 1, k + 10), Blocks.COBBLESTONE.getDefaultState());
        world.setBlockState(new BlockPos(i + 11, j + 1, k + 11), Blocks.COBBLESTONE.getDefaultState());
        world.setBlockState(new BlockPos(i + 11, j + 1, k + 12), Blocks.COBBLESTONE.getDefaultState());
        world.setBlockState(new BlockPos(i + 11, j + 2, k + 6), Blocks.COBBLESTONE.getDefaultState());
        world.setBlockState(new BlockPos(i + 11, j + 2, k + 7), Blocks.COBBLESTONE.getDefaultState());
        world.setBlockState(new BlockPos(i + 11, j + 2, k + 8), Blocks.COBBLESTONE.getDefaultState());
        world.setBlockState(new BlockPos(i + 11, j + 2, k + 9), Blocks.COBBLESTONE.getDefaultState());
        world.setBlockState(new BlockPos(i + 11, j + 2, k + 10), Blocks.MOSSY_COBBLESTONE.getDefaultState());
        world.setBlockState(new BlockPos(i + 11, j + 2, k + 11), Blocks.COBBLESTONE.getDefaultState());
        world.setBlockState(new BlockPos(i + 11, j + 2, k + 12), Blocks.COBBLESTONE.getDefaultState());
        world.setBlockState(new BlockPos(i + 11, j + 3, k + 6), Blocks.COBBLESTONE.getDefaultState());
        world.setBlockState(new BlockPos(i + 11, j + 3, k + 7), Blocks.COBBLESTONE.getDefaultState());
        world.setBlockState(new BlockPos(i + 11, j + 3, k + 8), Blocks.COBBLESTONE.getDefaultState());
        world.setBlockState(new BlockPos(i + 11, j + 3, k + 9), Blocks.MOSSY_COBBLESTONE.getDefaultState());
        world.setBlockState(new BlockPos(i + 11, j + 3, k + 10), Blocks.COBBLESTONE.getDefaultState());
        world.setBlockState(new BlockPos(i + 11, j + 3, k + 11), Blocks.COBBLESTONE.getDefaultState());
        world.setBlockState(new BlockPos(i + 11, j + 3, k + 12), Blocks.COBBLESTONE.getDefaultState());
        world.setBlockState(new BlockPos(i + 11, j + 4, k + 3), Blocks.COBBLESTONE.getDefaultState());
        world.setBlockState(new BlockPos(i + 11, j + 4, k + 4), Blocks.COBBLESTONE.getDefaultState());
        world.setBlockState(new BlockPos(i + 11, j + 4, k + 5), Blocks.COBBLESTONE.getDefaultState());
        world.setBlockState(new BlockPos(i + 11, j + 4, k + 6), Blocks.COBBLESTONE.getDefaultState());
        world.setBlockState(new BlockPos(i + 11, j + 4, k + 7), Blocks.STONE_STAIRS.getStateFromMeta(0));
        world.setBlockState(new BlockPos(i + 11, j + 4, k + 8), Blocks.STONE_STAIRS.getStateFromMeta(0));
        world.setBlockState(new BlockPos(i + 11, j + 4, k + 9), Blocks.STONE_STAIRS.getStateFromMeta(0));
        world.setBlockState(new BlockPos(i + 11, j + 4, k + 10), Blocks.STONE_STAIRS.getStateFromMeta(0));
        world.setBlockState(new BlockPos(i + 11, j + 4, k + 11), Blocks.STONE_STAIRS.getStateFromMeta(0));
        world.setBlockState(new BlockPos(i + 11, j + 4, k + 12), Blocks.COBBLESTONE.getDefaultState());
        world.setBlockState(new BlockPos(i + 11, j + 4, k + 13), Blocks.COBBLESTONE.getDefaultState());
        world.setBlockState(new BlockPos(i + 11, j + 4, k + 14), Blocks.COBBLESTONE.getDefaultState());
        world.setBlockState(new BlockPos(i + 11, j + 4, k + 15), Blocks.COBBLESTONE.getDefaultState());
        world.setBlockState(new BlockPos(i + 11, j + 5, k + 3), Blocks.COBBLESTONE.getDefaultState());
        world.setBlockState(new BlockPos(i + 11, j + 5, k + 6), Blocks.COBBLESTONE.getDefaultState());
        world.setBlockState(new BlockPos(i + 11, j + 5, k + 12), Blocks.COBBLESTONE.getDefaultState());
        world.setBlockState(new BlockPos(i + 11, j + 5, k + 15), Blocks.COBBLESTONE.getDefaultState());
        world.setBlockState(new BlockPos(i + 11, j + 6, k + 3), Blocks.MOSSY_COBBLESTONE.getDefaultState());
        world.setBlockState(new BlockPos(i + 11, j + 6, k + 6), Blocks.MOSSY_COBBLESTONE.getDefaultState());
        world.setBlockState(new BlockPos(i + 11, j + 6, k + 12), Blocks.COBBLESTONE.getDefaultState());
        world.setBlockState(new BlockPos(i + 11, j + 6, k + 15), Blocks.COBBLESTONE.getDefaultState());
        world.setBlockState(new BlockPos(i + 11, j + 7, k + 3), Blocks.COBBLESTONE.getDefaultState());
        world.setBlockState(new BlockPos(i + 11, j + 7, k + 6), Blocks.COBBLESTONE.getDefaultState());
        world.setBlockState(new BlockPos(i + 11, j + 7, k + 12), Blocks.MOSSY_COBBLESTONE.getDefaultState());
        world.setBlockState(new BlockPos(i + 11, j + 7, k + 15), Blocks.COBBLESTONE.getDefaultState());
        world.setBlockState(new BlockPos(i + 11, j + 8, k + 0), Blocks.DIRT.getDefaultState());
        world.setBlockState(new BlockPos(i + 11, j + 8, k + 1), Blocks.DIRT.getDefaultState());
        world.setBlockState(new BlockPos(i + 11, j + 8, k + 2), Blocks.DIRT.getDefaultState());
        world.setBlockState(new BlockPos(i + 11, j + 8, k + 3), Blocks.COBBLESTONE.getDefaultState());
        world.setBlockState(new BlockPos(i + 11, j + 8, k + 4), Blocks.COBBLESTONE.getDefaultState());
        world.setBlockState(new BlockPos(i + 11, j + 8, k + 5), Blocks.COBBLESTONE.getDefaultState());
        world.setBlockState(new BlockPos(i + 11, j + 8, k + 6), Blocks.COBBLESTONE.getDefaultState());
        world.setBlockState(new BlockPos(i + 11, j + 8, k + 7), Blocks.STONE_STAIRS.getStateFromMeta(4));
        world.setBlockState(new BlockPos(i + 11, j + 8, k + 8), Blocks.STONE_STAIRS.getStateFromMeta(4));
